Workbook

Sheet README
A1: HCR probe sets designed by Dragonaut9000
A2: This file holds one person's HCR probe sets. Every designer has their own file in the data folder of the HCR probe database, all with the same layout, and the probe finder viewer is built from all of them together.
A4: Sheets
A5: Probe_Sets has one row per gene × amplifier set; its pair counts come from Probe_Pairs, which has one row per P1/P2 pair linked by Set_ID. Templates holds target sequences if you have them (optional). Amplifiers is the reference list of initiator and spacer sequences, the same in every file.
A7: Set IDs
A8: Set IDs in this file start with "S" so they never clash with other people's files. Pair IDs are the Set_ID plus a two-digit pair number.
A10: Columns for you to fill in
A11: Headers in dark yellow are input columns (Status, Tube / location, Order date, Vendor / order ID, Notes); Status has a drop-down list. The other columns were filled when the file was built and checked: amplifier and P1/P2 were read from each oligo's own initiator, P1 and P2 were paired by position on the genome or template, and binding arms were matched against the NCBI B. anynana CDS (genome_cds.fa). Check notes summarizes anything worth a look; the pair-level detail is in the Pair flag column of Probe_Pairs.
A13: History
A14: Built from the original butterfly and zebrafish files, the per-gene and oPool sheets, set_1–3, genome_cds.fa and ncbi_annotation_ultimate.csv. Set IDs S001–S258 are kept from the first combined database.

Sheet Probe_Sets
A1: Set_ID | B1: Designed by | C1: Gene (short) | D1: Gene / protein name | E1: Organism | F1: LOC / GeneID | G1: NCBI accession | H1: Other ID | I1: Amplifier | J1: Fluorophore | K1: # pairs | L1: # pairs verified on template | M1: Same gene also on | N1: Names used in source files | O1: Source files | P1: Template(s) | Q1: LOC source | R1: Genome LOC (genome_cds.fa match) | S1: # pairs verified in genome | T1: Genome confidence | U1: NCBI protein name (genome_cds.fa) | V1: Name in ncbi_annotation_ultimate.csv | W1: XP accession(s) of genome LOC | X1: Check notes | Y1: Status | Z1: Tube / location | AA1: Order date | AB1: Vendor / order ID | AC1: Notes
A2: S001 | B2: Dragonaut9000 | C2: 18w | D2: 18 wheeler | E2: Bicyclus anynana | F2: LOC112047337 | I2: B1 | J2: AF546 | K2: =COUNTIF(Probe_Pairs!$B:$B,A2) -> 6 | L2: =COUNTIFS(Probe_Pairs!$B:$B,A2,Probe_Pairs!$S:$S,"Both halves") -> 6 | N2: 18w | O2: Master (Jul 2024); B1 file | P2: T050 | Q2: template header | R2: LOC112047337 | S2: =IF(R2="","",COUNTIFS(Probe_Pairs!$B:$B,A2,Probe_Pairs!$X:$X,"Both halves")) -> 6 | T2: =IF(R2="","",IF(S2*2>=K2,"High","Low")) -> High | U2: toll-like receptor 7 | V2: toll-like receptor 7 | W2: XP_023940195.2
A3: S002 | B3: Dragonaut9000 | C3: al-like | D3: aristaless-like | E3: Bicyclus anynana | F3: LOC112054675 | I3: B1 | J3: AF546 | K3: =COUNTIF(Probe_Pairs!$B:$B,A3) -> 4 | L3: =COUNTIFS(Probe_Pairs!$B:$B,A3,Probe_Pairs!$S:$S,"Both halves") -> 4 | N3: al_like | O3: Master (Jul 2024); B1 file | P3: T027 | Q3: template header | R3: LOC112054675 | S3: =IF(R3="","",COUNTIFS(Probe_Pairs!$B:$B,A3,Probe_Pairs!$X:$X,"Both halves")) -> 4 | T3: =IF(R3="","",IF(S3*2>=K3,"High","Low")) -> High | U3: homeobox protein aristaless isoform X2 | V3: homeobox protein aristaless-like | W3: XP_052747220.1; XP_052747221.1; XP_052747222.1
A4: S003 | B4: Dragonaut9000 | C4: APC | D4: adenomatous polyposis coli | E4: Bicyclus anynana | F4: LOC112047899 | G4: XM_024085194.1 | I4: B1 | J4: AF546 | K4: =COUNTIF(Probe_Pairs!$B:$B,A4) -> 3 | L4: =COUNTIFS(Probe_Pairs!$B:$B,A4,Probe_Pairs!$S:$S,"Both halves") -> 3 | M4: B2 | N4: APC | O4: Master (Jul 2024); B1 file | P4: T076 | Q4: genome_cds.fa match | R4: LOC112047899 | S4: =IF(R4="","",COUNTIFS(Probe_Pairs!$B:$B,A4,Probe_Pairs!$X:$X,"Both halves")) -> 2 | T4: =IF(R4="","",IF(S4*2>=K4,"High","Low")) -> High | U4: adenomatous polyposis coli protein isoform X4 | V4: adenomatous polyposis coli protein isoform X1 | W4: XP_052740051.1; XP_052740050.1; XP_052740043.1; XP_052740044.1; XP_052740045.1; XP_052740046.1; XP_052740047.1; XP_052740048.1; XP_052740049.1; XP_052740052.1
A5: S004 | B5: Dragonaut9000 | C5: araucan | D5: homeobox protein araucan isoform X2 | E5: Bicyclus anynana | F5: LOC112045732 | G5: XM_024082035.2 | I5: B1 | J5: AF546 | K5: =COUNTIF(Probe_Pairs!$B:$B,A5) -> 6 | L5: =COUNTIFS(Probe_Pairs!$B:$B,A5,Probe_Pairs!$S:$S,"Both halves") -> 6 | N5: araucan | O5: Master (Jul 2024); B1 file | P5: T037 | Q5: template header | R5: LOC112045732 | S5: =IF(R5="","",COUNTIFS(Probe_Pairs!$B:$B,A5,Probe_Pairs!$X:$X,"Both halves")) -> 6 | T5: =IF(R5="","",IF(S5*2>=K5,"High","Low")) -> High | U5: homeobox protein araucan isoform X2 | V5: homeobox protein araucan-like isoform X1 | W5: XP_023937802.1; XP_023937803.1
A6: S005 | B6: Dragonaut9000 | C6: aristaless | D6: aristaless | E6: Bicyclus anynana | F6: LOC112056678 | I6: B1 | J6: AF546 | K6: =COUNTIF(Probe_Pairs!$B:$B,A6) -> 10 | L6: =COUNTIFS(Probe_Pairs!$B:$B,A6,Probe_Pairs!$S:$S,"Both halves") -> 10 | N6: Arl | O6: Master (Jul 2024); B1 file | P6: T016 | Q6: genome_cds.fa match | R6: LOC112056678 | S6: =IF(R6="","",COUNTIFS(Probe_Pairs!$B:$B,A6,Probe_Pairs!$X:$X,"Both halves")) -> 6 | T6: =IF(R6="","",IF(S6*2>=K6,"High","Low")) -> High | U6: homeobox protein aristaless | V6: homeobox protein aristaless | W6: XP_023952906.1
A7: S006 | B7: Dragonaut9000 | C7: arm | D7: armadillo | E7: Bicyclus anynana | F7: LOC112048594 | I7: B1 | J7: AF546 | K7: =COUNTIF(Probe_Pairs!$B:$B,A7) -> 7 | L7: =COUNTIFS(Probe_Pairs!$B:$B,A7,Probe_Pairs!$S:$S,"Both halves") -> 7 | N7: arm | O7: Master (Jul 2024); B1 file | P7: T025 | Q7: genome_cds.fa match | R7: LOC112048594 | S7: =IF(R7="","",COUNTIFS(Probe_Pairs!$B:$B,A7,Probe_Pairs!$X:$X,"Both halves")) -> 5 | T7: =IF(R7="","",IF(S7*2>=K7,"High","Low")) -> High | U7: armadillo segment polarity protein isoform X4 | V7: armadillo segment polarity protein isoform X1 | W7: XP_052737433.1; XP_052737434.1; XP_052737432.1; XP_052737435.1
A8: S007 | B8: Dragonaut9000 | C8: bab1 | D8: protein bric-a-brac 1 isoform X2 | E8: Bicyclus anynana | F8: LOC112043806 | G8: XM_052890735.1 | I8: B1 | J8: AF546 | K8: =COUNTIF(Probe_Pairs!$B:$B,A8) -> 6 | L8: =COUNTIFS(Probe_Pairs!$B:$B,A8,Probe_Pairs!$S:$S,"Both halves") -> 6 | N8: bab1 | O8: Master (Jul 2024); B1 file | P8: T032 | Q8: template header | R8: LOC112043806 | S8: =IF(R8="","",COUNTIFS(Probe_Pairs!$B:$B,A8,Probe_Pairs!$X:$X,"Both halves")) -> 6 | T8: =IF(R8="","",IF(S8*2>=K8,"High","Low")) -> High | U8: protein bric-a-brac 1 isoform X1 | V8: protein bric-a-brac 1-like | W8: XP_052746695.1; XP_023935169.2; XP_052746694.1
A9: S008 | B9: Dragonaut9000 | C9: brinker | D9: brinker (atherin-like) | E9: Bicyclus anynana | F9: LOC112055415 | G9: XM_024095507.2 | I9: B1 | J9: AF546 | K9: =COUNTIF(Probe_Pairs!$B:$B,A9) -> 8 | L9: =COUNTIFS(Probe_Pairs!$B:$B,A9,Probe_Pairs!$S:$S,"Both halves") -> 8 | M9: B2 | N9: brinker | O9: Master (Jul 2024); B1 file | P9: T041 | Q9: template header | R9: LOC112055415 | S9: =IF(R9="","",COUNTIFS(Probe_Pairs!$B:$B,A9,Probe_Pairs!$X:$X,"Both halves")) -> 8 | T9: =IF(R9="","",IF(S9*2>=K9,"High","Low")) -> High | U9: atherin-like | V9: atherin-like(LOC112055415) | W9: XP_023951275.2
A10: S009 | B10: Dragonaut9000 | C10: ci | D10: cubitus interruptus | E10: Bicyclus anynana | F10: LOC112046560 | G10: XM_024083241.1 | I10: B1 | J10: AF546 | K10: =COUNTIF(Probe_Pairs!$B:$B,A10) -> 7 | L10: =COUNTIFS(Probe_Pairs!$B:$B,A10,Probe_Pairs!$S:$S,"Both halves") -> 7 | N10: ci | O10: Master (Jul 2024); B1 file | P10: T026 | Q10: genome_cds.fa match | R10: LOC112046560 | S10: =IF(R10="","",COUNTIFS(Probe_Pairs!$B:$B,A10,Probe_Pairs!$X:$X,"Both halves")) -> 6 | T10: =IF(R10="","",IF(S10*2>=K10,"High","Low")) -> High | U10: transcriptional activator cubitus interruptus | V10: transcriptional activator cubitus interruptus isoform X1 | W10: XP_023939008.1; XP_023939009.1
A11: S010 | B11: Dragonaut9000 | C11: cinnabar | D11: cinnabar (kynurenine 3-monooxygenase-like) | E11: Bicyclus anynana | F11: LOC112055866 | G11: XM_024096156.1 | I11: B1 | J11: AF546 | K11: =COUNTIF(Probe_Pairs!$B:$B,A11) -> 8 | L11: =COUNTIFS(Probe_Pairs!$B:$B,A11,Probe_Pairs!$S:$S,"Both halves") -> 8 | N11: cin | O11: Master (Jul 2024); B1 file | P11: T021 | Q11: template header | R11: LOC112055866 | S11: =IF(R11="","",COUNTIFS(Probe_Pairs!$B:$B,A11,Probe_Pairs!$X:$X,"Both halves")) -> 6 | T11: =IF(R11="","",IF(S11*2>=K11,"High","Low")) -> High | U11: kynurenine 3-monooxygenase | V11: kynurenine 3-monooxygenase-like | W11: XP_023951924.2
A12: S011 | B12: Dragonaut9000 | C12: CK1 | D12: casein kinase I | E12: Bicyclus anynana | F12: LOC112055421 | G12: XM_024095515.1 | I12: B1 | J12: AF546 | K12: =COUNTIF(Probe_Pairs!$B:$B,A12) -> 3 | L12: =COUNTIFS(Probe_Pairs!$B:$B,A12,Probe_Pairs!$S:$S,"Both halves") -> 3 | M12: B3 | N12: CK1 | O12: Master (Jul 2024); B1 file | P12: T081 | Q12: genome_cds.fa match | R12: LOC112055421 | S12: =IF(R12="","",COUNTIFS(Probe_Pairs!$B:$B,A12,Probe_Pairs!$X:$X,"Both halves")) -> 3 | T12: =IF(R12="","",IF(S12*2>=K12,"High","Low")) -> High | U12: casein kinase I isoform X4 | V12: casein kinase I isoform X1 | W12: XP_052742577.1; XP_052742578.1; XP_052742579.1; XP_052742580.1; XP_052742582.1; XP_052742583.1; XP_052742584.1; XP_052742585.1; XP_052742586.1; XP_052742588.1; XP_052742587.1; XP_052742590.1; XP_052742589.1
A13: S012 | B13: Dragonaut9000 | C13: delta | D13: neurogenic locus protein delta | E13: Bicyclus anynana | F13: LOC112046850 | I13: B1 | J13: AF546 | K13: =COUNTIF(Probe_Pairs!$B:$B,A13) -> 6 | L13: =COUNTIFS(Probe_Pairs!$B:$B,A13,Probe_Pairs!$S:$S,"Both halves") -> 6 | N13: delta | O13: Master (Jul 2024); B1 file | P13: T029 | Q13: template header | R13: LOC112046850 | S13: =IF(R13="","",COUNTIFS(Probe_Pairs!$B:$B,A13,Probe_Pairs!$X:$X,"Both halves")) -> 6 | T13: =IF(R13="","",IF(S13*2>=K13,"High","Low")) -> High | U13: neurogenic locus protein delta | V13: neurogenic locus protein delta-like(LOC112046850) | W13: XP_052744326.1
A14: S013 | B14: Dragonaut9000 | C14: dopr2 | D14: dopamine receptor 2-like | E14: Bicyclus anynana | F14: LOC112056723 | G14: XM_052888388.1 | I14: B1 | J14: AF546 | K14: =COUNTIF(Probe_Pairs!$B:$B,A14) -> 8 | L14: =COUNTIFS(Probe_Pairs!$B:$B,A14,Probe_Pairs!$S:$S,"Both halves") -> 8 | N14: dopr2 | O14: Master (Jul 2024) | P14: T154 | Q14: template header | R14: LOC112056723 | S14: =IF(R14="","",COUNTIFS(Probe_Pairs!$B:$B,A14,Probe_Pairs!$X:$X,"Both halves")) -> 8 | T14: =IF(R14="","",IF(S14*2>=K14,"High","Low")) -> High | U14: dopamine receptor 2-like | V14: dopamine receptor 2-like(LOC112056723) | W14: XP_052744348.1
A15: S014 | B15: Dragonaut9000 | C15: dpp | D15: decapentaplegic | E15: Bicyclus anynana | F15: LOC112044871 | I15: B1 | J15: AF546 | K15: =COUNTIF(Probe_Pairs!$B:$B,A15) -> 10 | L15: =COUNTIFS(Probe_Pairs!$B:$B,A15,Probe_Pairs!$S:$S,"Both halves") -> 10 | M15: B4 | N15: Dpp | O15: Master (Jul 2024); B1 file | P15: T005 | Q15: genome_cds.fa match | R15: LOC112044871 | S15: =IF(R15="","",COUNTIFS(Probe_Pairs!$B:$B,A15,Probe_Pairs!$X:$X,"Both halves")) -> 7 | T15: =IF(R15="","",IF(S15*2>=K15,"High","Low")) -> High | U15: protein decapentaplegic | V15: protein decapentaplegic | W15: XP_023936626.1; XP_052739615.1
A16: S015 | B16: Dragonaut9000 | C16: ds | D16: Protein Dachsous | E16: Bicyclus anynana | F16: LOC112058497 | I16: B1 | J16: AF546 | K16: =COUNTIF(Probe_Pairs!$B:$B,A16) -> 10 | L16: =COUNTIFS(Probe_Pairs!$B:$B,A16,Probe_Pairs!$S:$S,"Both halves") -> 10 | N16: ds | O16: ds_dsx_ets5 oPool | P16: T190 | Q16: template header | R16: LOC112058497 | S16: =IF(R16="","",COUNTIFS(Probe_Pairs!$B:$B,A16,Probe_Pairs!$X:$X,"Both halves")) -> 10 | T16: =IF(R16="","",IF(S16*2>=K16,"High","Low")) -> High | U16: protein dachsous | V16: protein dachsous | W16: XP_023955141.2; XP_052739607.1
A17: S016 | B17: Dragonaut9000 | C17: dscam2 | D17: cell adhesion molecule Dscam2-like | E17: Bicyclus anynana | F17: LOC112043786 | G17: XM_024079361.2 | I17: B1 | J17: AF546 | K17: =COUNTIF(Probe_Pairs!$B:$B,A17) -> 6 | L17: =COUNTIFS(Probe_Pairs!$B:$B,A17,Probe_Pairs!$S:$S,"Both halves") -> 6 | N17: dscam2 | O17: Master (Jul 2024); B1 file | P17: T042 | Q17: template header | R17: LOC112043786 | S17: =IF(R17="","",COUNTIFS(Probe_Pairs!$B:$B,A17,Probe_Pairs!$X:$X,"Both halves")) -> 6 | T17: =IF(R17="","",IF(S17*2>=K17,"High","Low")) -> High | U17: cell adhesion molecule Dscam2-like | V17: Down syndrome cell adhesion molecule-like protein Dscam2 | W17: XP_023935129.2
A18: S017 | B18: Dragonaut9000 | C18: e20m | D18: ecdysone 20-monooxygenase isoform X2 | E18: Bicyclus anynana | F18: LOC112056276 | G18: XM_052888368.1 | I18: B1 | J18: AF546 | K18: =COUNTIF(Probe_Pairs!$B:$B,A18) -> 6 | L18: =COUNTIFS(Probe_Pairs!$B:$B,A18,Probe_Pairs!$S:$S,"Both halves") -> 6 | N18: e20m | O18: Master (Jul 2024); B1 file | P18: T033 | Q18: template header | R18: LOC112056276 | S18: =IF(R18="","",COUNTIFS(Probe_Pairs!$B:$B,A18,Probe_Pairs!$X:$X,"Both halves")) -> 6 | T18: =IF(R18="","",IF(S18*2>=K18,"High","Low")) -> High | U18: ecdysone 20-monooxygenase isoform X2 | V18: ecdysone 20-monooxygenase isoform X1 | W18: XP_052744327.1; XP_052744328.1
A19: S018 | B19: Dragonaut9000 | C19: en | D19: engrailed | E19: Bicyclus anynana | F19: LOC112053007 | I19: B1 | J19: AF546 | K19: =COUNTIF(Probe_Pairs!$B:$B,A19) -> 9 | L19: =COUNTIFS(Probe_Pairs!$B:$B,A19,Probe_Pairs!$S:$S,"Both halves") -> 9 | M19: B3 | N19: en | O19: Master (Jul 2024); B1 file | P19: T009 | Q19: genome_cds.fa match | R19: LOC112053007 | S19: =IF(R19="","",COUNTIFS(Probe_Pairs!$B:$B,A19,Probe_Pairs!$X:$X,"Both halves")) -> 5 | T19: =IF(R19="","",IF(S19*2>=K19,"High","Low")) -> High | U19: segmentation polarity homeobox protein engrailed | V19: segmentation polarity homeobox protein engrailed-like | W19: XP_023948032.2
A20: S019 | B20: Dragonaut9000 | C20: ensl | D20: enhancer of split mbeta protein-like | E20: Bicyclus anynana | F20: LOC112051893 | G20: XM_024090728.2 | I20: B1 | J20: AF546 | K20: =COUNTIF(Probe_Pairs!$B:$B,A20) -> 6 | L20: =COUNTIFS(Probe_Pairs!$B:$B,A20,Probe_Pairs!$S:$S,"Both halves") -> 6 | N20: ensl | O20: Master (Jul 2024); B1 file | P20: T049 | Q20: template header | R20: LOC112051893 | S20: =IF(R20="","",COUNTIFS(Probe_Pairs!$B:$B,A20,Probe_Pairs!$X:$X,"Both halves")) -> 6 | T20: =IF(R20="","",IF(S20*2>=K20,"High","Low")) -> High | U20: enhancer of split mbeta protein-like | V20: enhancer of split mbeta protein-like | W20: XP_023946496.2
A21: S020 | B21: Dragonaut9000 | C21: eve | D21: even-skipped | E21: Bicyclus anynana | F21: LOC112051685 | I21: B1 | J21: AF546 | K21: =COUNTIF(Probe_Pairs!$B:$B,A21) -> 6 | L21: =COUNTIFS(Probe_Pairs!$B:$B,A21,Probe_Pairs!$S:$S,"Both halves") -> 6 | N21: eve | O21: Master (Jul 2024); B1 file | P21: T018 | Q21: genome_cds.fa match | R21: LOC112051685 | S21: =IF(R21="","",COUNTIFS(Probe_Pairs!$B:$B,A21,Probe_Pairs!$X:$X,"Both halves")) -> 3 | T21: =IF(R21="","",IF(S21*2>=K21,"High","Low")) -> High | U21: segmentation protein even-skipped-like isoform X2 | V21: segmentation protein even-skipped-like isoform X1 | W21: XP_023946223.1; XP_023946224.1
A22: S021 | B22: Dragonaut9000 | C22: franky | D22: uncharacterized protein LOC112044027 | E22: Bicyclus anynana | F22: LOC112044027 | G22: XM_024079746.2 | I22: B1 | J22: AF546 | K22: =COUNTIF(Probe_Pairs!$B:$B,A22) -> 6 | L22: =COUNTIFS(Probe_Pairs!$B:$B,A22,Probe_Pairs!$S:$S,"Both halves") -> 6 | N22: franky | O22: Master (Jul 2024); B1 file | P22: T045 | Q22: template header | R22: LOC112044027 | S22: =IF(R22="","",COUNTIFS(Probe_Pairs!$B:$B,A22,Probe_Pairs!$X:$X,"Both halves")) -> 6 | T22: =IF(R22="","",IF(S22*2>=K22,"High","Low")) -> High | U22: uncharacterized protein LOC112044027 | V22: cytochrome c oxidase assembly factor 6 homolog isoform X2 | W22: XP_023935514.2
A23: S022 | B23: Dragonaut9000 | C23: gasp1 | D23: growth arrest-specific protein 1 | E23: Bicyclus anynana | F23: LOC112057967 | G23: XM_024098582.2 | I23: B1 | J23: AF546 | K23: =COUNTIF(Probe_Pairs!$B:$B,A23) -> 6 | L23: =COUNTIFS(Probe_Pairs!$B:$B,A23,Probe_Pairs!$S:$S,"Both halves") -> 6 | N23: gasp1 | O23: Master (Jul 2024); B1 file | P23: T035 | Q23: template header | R23: LOC112057967 | S23: =IF(R23="","",COUNTIFS(Probe_Pairs!$B:$B,A23,Probe_Pairs!$X:$X,"Both halves")) -> 6 | T23: =IF(R23="","",IF(S23*2>=K23,"High","Low")) -> High | U23: growth arrest-specific protein 1 | V23: growth arrest-specific protein 1-like | W23: XP_023954350.2
A24: S023 | B24: Dragonaut9000 | C24: GFP | D24: GFP | E24: — (GFP transgene) | I24: B1 | J24: AF546 | K24: =COUNTIF(Probe_Pairs!$B:$B,A24) -> 8 | L24: =COUNTIFS(Probe_Pairs!$B:$B,A24,Probe_Pairs!$S:$S,"Both halves") -> 8 | N24: gfp | O24: Master (Jul 2024); B1 file | P24: T023 | S24: =IF(R24="","",COUNTIFS(Probe_Pairs!$B:$B,A24,Probe_Pairs!$X:$X,"Both halves")) | T24: =IF(R24="","",IF(S24*2>=K24,"High","Low")) | X24: 1 pair(s) flagged in Probe_Pairs
A25: S024 | B25: Dragonaut9000 | C25: groucho-like | D25: groucho-like | E25: Bicyclus anynana | F25: LOC112044658 | G25: XM_024080563.1 | I25: B1 | J25: AF546 | K25: =COUNTIF(Probe_Pairs!$B:$B,A25) -> 3 | L25: =COUNTIFS(Probe_Pairs!$B:$B,A25,Probe_Pairs!$S:$S,"Both halves") -> 3 | M25: B2 | N25: groucho-like | O25: Master (Jul 2024); B1 file | P25: T074 | Q25: genome_cds.fa match | R25: LOC112044658 | S25: =IF(R25="","",COUNTIFS(Probe_Pairs!$B:$B,A25,Probe_Pairs!$X:$X,"Both halves")) -> 3 | T25: =IF(R25="","",IF(S25*2>=K25,"High","Low")) -> High | U25: protein groucho | V25: protein groucho-like isoform X1 | W25: XP_052742340.1
A26: S025 | B26: Dragonaut9000 | C26: hsp67B1 | D26: heat shock protein 67B1-like | E26: Bicyclus anynana | F26: LOC112054669 | G26: XM_024094531.2 | I26: B1 | J26: AF546 | K26: =COUNTIF(Probe_Pairs!$B:$B,A26) -> 6 | L26: =COUNTIFS(Probe_Pairs!$B:$B,A26,Probe_Pairs!$S:$S,"Both halves") -> 6 | N26: hsp67B1 | O26: Master (Jul 2024); B1 file | P26: T036 | Q26: template header | R26: LOC112054669 | S26: =IF(R26="","",COUNTIFS(Probe_Pairs!$B:$B,A26,Probe_Pairs!$X:$X,"Both halves")) -> 6 | T26: =IF(R26="","",IF(S26*2>=K26,"High","Low")) -> High | U26: heat shock protein 67B1-like | V26: heat shock protein 67B1-like | W26: XP_023950299.2
A27: S026 | B27: Dragonaut9000 | C27: hth | D27: homothorax | E27: Bicyclus anynana | F27: LOC112054591 | I27: B1 | J27: AF546 | K27: =COUNTIF(Probe_Pairs!$B:$B,A27) -> 6 | L27: =COUNTIFS(Probe_Pairs!$B:$B,A27,Probe_Pairs!$S:$S,"Both halves") -> 5 | M27: B3 | N27: Htha, Hthb, Hthc, hth | O27: Master (Jul 2024); B1 file | P27: T019 | Q27: genome_cds.fa match | R27: LOC112054591 | S27: =IF(R27="","",COUNTIFS(Probe_Pairs!$B:$B,A27,Probe_Pairs!$X:$X,"Both halves")) -> 5 | T27: =IF(R27="","",IF(S27*2>=K27,"High","Low")) -> High | U27: homeobox protein homothorax isoform X4 | V27: homeobox protein homothorax isoform X1 | W27: XP_052744213.1; XP_052744214.1; XP_023950201.1; XP_052744215.1 | X27: 1 pair(s) flagged in Probe_Pairs
A28: S027 | B28: Dragonaut9000 | C28: inv | D28: invected | E28: Bicyclus anynana | F28: LOC112053006 | I28: B1 | J28: AF546 | K28: =COUNTIF(Probe_Pairs!$B:$B,A28) -> 10 | L28: =COUNTIFS(Probe_Pairs!$B:$B,A28,Probe_Pairs!$S:$S,"Both halves") -> 10 | N28: inv | O28: Master (Jul 2024); B1 file | P28: T011 | Q28: genome_cds.fa match | R28: LOC112053006 | S28: =IF(R28="","",COUNTIFS(Probe_Pairs!$B:$B,A28,Probe_Pairs!$X:$X,"Both halves")) -> 7 | T28: =IF(R28="","",IF(S28*2>=K28,"High","Low")) -> High | U28: homeobox protein invected-like isoform X2 | V28: homeobox protein invected-like isoform X1 | W28: XP_052742906.1; XP_052742907.1
A29: S028 | B29: Dragonaut9000 | C29: invected-like | D29: invected-like | E29: Bicyclus anynana | I29: B1 | J29: AF546 | K29: =COUNTIF(Probe_Pairs!$B:$B,A29) -> 3 | L29: =COUNTIFS(Probe_Pairs!$B:$B,A29,Probe_Pairs!$S:$S,"Both halves") -> 3 | N29: invlike | O29: Master (Jul 2024); B1 file | P29: T010 | S29: =IF(R29="","",COUNTIFS(Probe_Pairs!$B:$B,A29,Probe_Pairs!$X:$X,"Both halves")) | T29: =IF(R29="","",IF(S29*2>=K29,"High","Low"))
A30: S029 | B30: Dragonaut9000 | C30: kartic | D30: uncharacterized protein LOC112043273 isoform X2 | E30: Bicyclus anynana | F30: LOC112043273 | G30: XM_052891417.1 | I30: B1 | J30: AF546 | K30: =COUNTIF(Probe_Pairs!$B:$B,A30) -> 6 | L30: =COUNTIFS(Probe_Pairs!$B:$B,A30,Probe_Pairs!$S:$S,"Both halves") -> 6 | N30: kartic | O30: Master (Jul 2024); B1 file | P30: T044 | Q30: template header | R30: LOC112043273 | S30: =IF(R30="","",COUNTIFS(Probe_Pairs!$B:$B,A30,Probe_Pairs!$X:$X,"Both halves")) -> 6 | T30: =IF(R30="","",IF(S30*2>=K30,"High","Low")) -> High | U30: uncharacterized protein LOC112043273 isoform X2 | V30: uncharacterized LOC112043273(LOC112043273) | W30: XP_023934361.2; XP_052747377.1
A31: S030 | B31: Dragonaut9000 | C31: kfase | D31: kynurenine formamidase | E31: Bicyclus anynana | F31: LOC112055308 | G31: XM_024095364.1 | I31: B1 | J31: AF546 | K31: =COUNTIF(Probe_Pairs!$B:$B,A31) -> 8 | L31: =COUNTIFS(Probe_Pairs!$B:$B,A31,Probe_Pairs!$S:$S,"Both halves") -> 8 | N31: kfase | O31: Master (Jul 2024); B1 file | P31: T022 | Q31: template header | R31: LOC112055308 | S31: =IF(R31="","",COUNTIFS(Probe_Pairs!$B:$B,A31,Probe_Pairs!$X:$X,"Both halves")) -> 3 | T31: =IF(R31="","",IF(S31*2>=K31,"High","Low")) -> Low | U31: kynurenine formamidase isoform X2 | V31: kynurenine formamidase isoform X1 | W31: XP_023951131.2; XP_023951132.2; XP_023951133.2 | X31: Only 3/8 pairs match the genome LOC on both halves
A32: S031 | B32: Dragonaut9000 | C32: knirps | D32: knirps | E32: Bicyclus anynana | F32: LOC112043430 | I32: B1 | J32: AF546 | K32: =COUNTIF(Probe_Pairs!$B:$B,A32) -> 10 | L32: =COUNTIFS(Probe_Pairs!$B:$B,A32,Probe_Pairs!$S:$S,"Both halves") -> 10 | N32: Kni | O32: Master (Jul 2024); B1 file | P32: T017 | Q32: genome_cds.fa match | R32: LOC112043430 | S32: =IF(R32="","",COUNTIFS(Probe_Pairs!$B:$B,A32,Probe_Pairs!$X:$X,"Both halves")) -> 6 | T32: =IF(R32="","",IF(S32*2>=K32,"High","Low")) -> High | U32: knirps-related protein-like | V32: knirps-related protein-like | W32: XP_023934605.1 | X32: 1 pair(s) flagged in Probe_Pairs
A33: S032 | B33: Dragonaut9000 | C33: lachesin | D33: lachesin-like | E33: Bicyclus anynana | F33: LOC112042983 | G33: XM_024078217.2 | I33: B1 | J33: AF546 | K33: =COUNTIF(Probe_Pairs!$B:$B,A33) -> 6 | L33: =COUNTIFS(Probe_Pairs!$B:$B,A33,Probe_Pairs!$S:$S,"Both halves") -> 6 | N33: lachesin | O33: Master (Jul 2024); B1 file | P33: T043 | Q33: template header | R33: LOC112042983 | S33: =IF(R33="","",COUNTIFS(Probe_Pairs!$B:$B,A33,Probe_Pairs!$X:$X,"Both halves")) -> 6 | T33: =IF(R33="","",IF(S33*2>=K33,"High","Low")) -> High | U33: lachesin-like | V33: lachesin-like | W33: XP_023933985.1
A34: S033 | B34: Dragonaut9000 | C34: lethal2 | D34: protein lethal(2)essential for life | E34: Bicyclus anynana | F34: LOC112054673 | G34: XM_024094536.2 | I34: B1 | J34: AF546 | K34: =COUNTIF(Probe_Pairs!$B:$B,A34) -> 6 | L34: =COUNTIFS(Probe_Pairs!$B:$B,A34,Probe_Pairs!$S:$S,"Both halves") -> 6 | N34: lethal2 | O34: Master (Jul 2024); B1 file | P34: T039 | Q34: template header | R34: LOC112054673 | S34: =IF(R34="","",COUNTIFS(Probe_Pairs!$B:$B,A34,Probe_Pairs!$X:$X,"Both halves")) -> 6 | T34: =IF(R34="","",IF(S34*2>=K34,"High","Low")) -> High | U34: protein lethal(2)essential for life | V34: protein lethal(2)essential for life-like | W34: XP_023950304.1
A35: S034 | B35: Dragonaut9000 | C35: mad6 | D35: mothers against decapentaplegic homolog 6 | E35: Bicyclus anynana | F35: LOC112050707 | H35: Bany_10682-RB | I35: B1 | J35: AF546 | K35: =COUNTIF(Probe_Pairs!$B:$B,A35) -> 5 | L35: =COUNTIFS(Probe_Pairs!$B:$B,A35,Probe_Pairs!$S:$S,"Both halves") -> 5 | M35: B3 | N35: Mad | O35: Master (Jul 2024); B1 file | P35: T047 | Q35: genome_cds.fa match | R35: LOC112050707 | S35: =IF(R35="","",COUNTIFS(Probe_Pairs!$B:$B,A35,Probe_Pairs!$X:$X,"Both halves")) -> 5 | T35: =IF(R35="","",IF(S35*2>=K35,"High","Low")) -> High | U35: mothers against decapentaplegic homolog 6 | V35: mothers against decapentaplegic homolog 6 | W35: XP_023944813.2
A36: S035 | B36: Dragonaut9000 | C36: miR-2788-5p | E36: Bicyclus anynana | I36: B1 | J36: AF546 | K36: =COUNTIF(Probe_Pairs!$B:$B,A36) -> 1 | L36: =COUNTIFS(Probe_Pairs!$B:$B,A36,Probe_Pairs!$S:$S,"Both halves") -> 1 | N36: Mir | O36: Master (Jul 2024); B1 file | P36: T202 | S36: =IF(R36="","",COUNTIFS(Probe_Pairs!$B:$B,A36,Probe_Pairs!$X:$X,"Both halves")) | T36: =IF(R36="","",IF(S36*2>=K36,"High","Low")) | X36: 1 pair(s) flagged in Probe_Pairs
A37: S036 | B37: Dragonaut9000 | C37: mth2 | D37: G-protein coupled receptor Mth2 | E37: Bicyclus anynana | F37: LOC112055720 | G37: XR_008251439.1 | I37: B1 | J37: AF546 | K37: =COUNTIF(Probe_Pairs!$B:$B,A37) -> 6 | L37: =COUNTIFS(Probe_Pairs!$B:$B,A37,Probe_Pairs!$S:$S,"Both halves") -> 6 | N37: mth2 | O37: Master (Jul 2024); B1 file | P37: T040 | Q37: template header | R37: LOC112055720 | S37: =IF(R37="","",COUNTIFS(Probe_Pairs!$B:$B,A37,Probe_Pairs!$X:$X,"Both halves")) -> 6 | T37: =IF(R37="","",IF(S37*2>=K37,"High","Low")) -> High | U37: G-protein coupled receptor Mth2 | V37: G-protein coupled receptor Mth2-like isoform X1 | W37: XP_052741340.1
A38: S037 | B38: Dragonaut9000 | C38: net | D38: transcription factor ATOH8 | E38: Bicyclus anynana | F38: LOC112055221 | G38: XM_024095242.2 | I38: B1 | J38: AF546 | K38: =COUNTIF(Probe_Pairs!$B:$B,A38) -> 10 | L38: =COUNTIFS(Probe_Pairs!$B:$B,A38,Probe_Pairs!$S:$S,"Both halves") -> 10 | N38: net | O38: Master (Jul 2024) | P38: T163 | Q38: template header | R38: LOC112055221 | S38: =IF(R38="","",COUNTIFS(Probe_Pairs!$B:$B,A38,Probe_Pairs!$X:$X,"Both halves")) -> 10 | T38: =IF(R38="","",IF(S38*2>=K38,"High","Low")) -> High | U38: transcription factor ATOH8 | V38: protein atonal homolog 8 | W38: XP_023951010.2
A39: S038 | B39: Dragonaut9000 | C39: nhl-1 | D39: RING finger protein nhl-1 isoform X2 | E39: Bicyclus anynana | F39: LOC112045027 | G39: XM_052885655.1 | I39: B1 | J39: AF546 | K39: =COUNTIF(Probe_Pairs!$B:$B,A39) -> 6 | L39: =COUNTIFS(Probe_Pairs!$B:$B,A39,Probe_Pairs!$S:$S,"Both halves") -> 6 | N39: nhl-1 | O39: Master (Jul 2024); B1 file | P39: T046 | Q39: template header | R39: LOC112045027 | S39: =IF(R39="","",COUNTIFS(Probe_Pairs!$B:$B,A39,Probe_Pairs!$X:$X,"Both halves")) -> 6 | T39: =IF(R39="","",IF(S39*2>=K39,"High","Low")) -> High | U39: RING finger protein nhl-1 isoform X1 | V39: RING finger protein nhl-1 isoform X1 | W39: XP_052741615.1; XP_023936835.1; XP_023936836.1; XP_052741612.1; XP_052741613.1
A40: S039 | B40: Dragonaut9000 | C40: notch1 | D40: neurogenic locus Notch protein isoform X1 | E40: Bicyclus anynana | F40: LOC112052049 | I40: B1 | J40: AF546 | K40: =COUNTIF(Probe_Pairs!$B:$B,A40) -> 6 | L40: =COUNTIFS(Probe_Pairs!$B:$B,A40,Probe_Pairs!$S:$S,"Both halves") -> 6 | N40: notch1 | O40: Master (Jul 2024); B1 file | P40: T028 | Q40: template header | R40: LOC112052049 | S40: =IF(R40="","",COUNTIFS(Probe_Pairs!$B:$B,A40,Probe_Pairs!$X:$X,"Both halves")) -> 6 | T40: =IF(R40="","",IF(S40*2>=K40,"High","Low")) -> High | U40: neurogenic locus Notch protein isoform X2 | V40: neurogenic locus Notch protein isoform X1 | W40: XP_052737293.1; XP_052737294.1
...

Sheet Probe_Pairs
A1: Pair_ID | B1: Set_ID | C1: Gene | D1: Amplifier | E1: Pair # | F1: P1 standard name | G1: P1 sequence (5′→3′) | H1: P2 standard name | I1: P2 sequence (5′→3′) | J1: P1 original name(s) | K1: P2 original name(s) | L1: P1 binding arm | M1: P2 binding arm | N1: P1 arm length | O1: P2 arm length | P1: P1 arm GC% | Q1: P2 arm GC% | R1: Template | S1: Template match | T1: Site start on template (nt) | U1: Paired by | V1: Source files | W1: Pool / order (as recorded) | X1: Genome match (to set LOC) | Y1: Pair flag
A2: S001-01 | B2: S001 | C2: 18w | D2: B1 | E2: 1 | F2: 18w_B1_P1_01 | G2: GAGGAGGGCAGCAAACGGAAAAATATATTTCTCGCAACTCTTTCG | H2: 18w_B1_P2_01 | I2: GCTAATTCAAATAGTAGGTTATTATTAGAAGAGTCTTCCTTTACG | J2: B1_P1 (18w)_1 | K2: B1_P2 (18w)_1 | L2: AAATATATTTCTCGCAACTCTTTCG | M2: GCTAATTCAAATAGTAGGTTATTAT | N2: =LEN(L2) -> 25 | O2: =LEN(M2) -> 25 | P2: =IF(N2=0,"",(N2-LEN(SUBSTITUTE(SUBSTITUTE(L2,"G",""),"C","")))/N2) -> 0.32 | Q2: =IF(O2=0,"",(O2-LEN(SUBSTITUTE(SUBSTITUTE(M2,"G",""),"C","")))/O2) -> 0.24 | R2: T050 | S2: Both halves | T2: 210 | U2: template position | V2: Master (Jul 2024); B1 file | X2: Both halves
A3: S001-02 | B3: S001 | C3: 18w | D3: B1 | E3: 2 | F3: 18w_B1_P1_02 | G3: GAGGAGGGCAGCAAACGGAATAAGACAAGCAGCTGTTCTAATCGG | H3: 18w_B1_P2_02 | I3: ACTTGAGAGTTGATTATTCGATAAATAGAAGAGTCTTCCTTTACG | J3: B1_P1 (18w)_2 | K3: B1_P2 (18w)_2 | L3: TAAGACAAGCAGCTGTTCTAATCGG | M3: ACTTGAGAGTTGATTATTCGATAAA | N3: =LEN(L3) -> 25 | O3: =LEN(M3) -> 25 | P3: =IF(N3=0,"",(N3-LEN(SUBSTITUTE(SUBSTITUTE(L3,"G",""),"C","")))/N3) -> 0.44 | Q3: =IF(O3=0,"",(O3-LEN(SUBSTITUTE(SUBSTITUTE(M3,"G",""),"C","")))/O3) -> 0.28 | R3: T050 | S3: Both halves | T3: 277 | U3: template position | V3: Master (Jul 2024); B1 file | X3: Both halves
A4: S001-03 | B4: S001 | C4: 18w | D4: B1 | E4: 3 | F4: 18w_B1_P1_03 | G4: GAGGAGGGCAGCAAACGGAAAAGCGTATAAGACCAATGAAAGTTC | H4: 18w_B1_P2_03 | I4: GCGTTATTGGATAAATTCAGAATGATAGAAGAGTCTTCCTTTACG | J4: B1_P1 (18w)_3 | K4: B1_P2 (18w)_3 | L4: AAGCGTATAAGACCAATGAAAGTTC | M4: GCGTTATTGGATAAATTCAGAATGA | N4: =LEN(L4) -> 25 | O4: =LEN(M4) -> 25 | P4: =IF(N4=0,"",(N4-LEN(SUBSTITUTE(SUBSTITUTE(L4,"G",""),"C","")))/N4) -> 0.36 | Q4: =IF(O4=0,"",(O4-LEN(SUBSTITUTE(SUBSTITUTE(M4,"G",""),"C","")))/O4) -> 0.32 | R4: T050 | S4: Both halves | T4: 345 | U4: template position | V4: Master (Jul 2024); B1 file | X4: Both halves
A5: S001-04 | B5: S001 | C5: 18w | D5: B1 | E5: 4 | F5: 18w_B1_P1_04 | G5: GAGGAGGGCAGCAAACGGAAAGAATAAATCCTTGAACGTCTTACC | H5: 18w_B1_P2_04 | I5: TATTTCTTAAATCTAATATTTGAAGTAGAAGAGTCTTCCTTTACG | J5: B1_P1 (18w)_4 | K5: B1_P2 (18w)_4 | L5: AGAATAAATCCTTGAACGTCTTACC | M5: TATTTCTTAAATCTAATATTTGAAG | N5: =LEN(L5) -> 25 | O5: =LEN(M5) -> 25 | P5: =IF(N5=0,"",(N5-LEN(SUBSTITUTE(SUBSTITUTE(L5,"G",""),"C","")))/N5) -> 0.36 | Q5: =IF(O5=0,"",(O5-LEN(SUBSTITUTE(SUBSTITUTE(M5,"G",""),"C","")))/O5) -> 0.16 | R5: T050 | S5: Both halves | T5: 413 | U5: template position | V5: Master (Jul 2024); B1 file | X5: Both halves
A6: S001-05 | B6: S001 | C6: 18w | D6: B1 | E6: 5 | F6: 18w_B1_P1_05 | G6: GAGGAGGGCAGCAAACGGAACAAAGGAAGGAAAGTATTCTCTTCA | H6: 18w_B1_P2_05 | I6: AGCTAAGTTTATAGTATGTAAATTATAGAAGAGTCTTCCTTTACG | J6: B1_P1 (18w)_5 | K6: B1_P2 (18w)_5 | L6: CAAAGGAAGGAAAGTATTCTCTTCA | M6: AGCTAAGTTTATAGTATGTAAATTA | N6: =LEN(L6) -> 25 | O6: =LEN(M6) -> 25 | P6: =IF(N6=0,"",(N6-LEN(SUBSTITUTE(SUBSTITUTE(L6,"G",""),"C","")))/N6) -> 0.36 | Q6: =IF(O6=0,"",(O6-LEN(SUBSTITUTE(SUBSTITUTE(M6,"G",""),"C","")))/O6) -> 0.2 | R6: T050 | S6: Both halves | T6: 481 | U6: template position | V6: Master (Jul 2024); B1 file | X6: Both halves
A7: S001-06 | B7: S001 | C7: 18w | D7: B1 | E7: 6 | F7: 18w_B1_P1_06 | G7: GAGGAGGGCAGCAAACGGAAGCCATTAAAAAGGAGCTCATCGATA | H7: 18w_B1_P2_06 | I7: TAAATTCAATTTACTTAAAACAAACTAGAAGAGTCTTCCTTTACG | J7: B1_P1 (18w)_6 | K7: B1_P2 (18w)_6 | L7: GCCATTAAAAAGGAGCTCATCGATA | M7: TAAATTCAATTTACTTAAAACAAAC | N7: =LEN(L7) -> 25 | O7: =LEN(M7) -> 25 | P7: =IF(N7=0,"",(N7-LEN(SUBSTITUTE(SUBSTITUTE(L7,"G",""),"C","")))/N7) -> 0.4 | Q7: =IF(O7=0,"",(O7-LEN(SUBSTITUTE(SUBSTITUTE(M7,"G",""),"C","")))/O7) -> 0.16 | R7: T050 | S7: Both halves | T7: 550 | U7: template position | V7: Master (Jul 2024); B1 file | X7: Both halves
A8: S002-01 | B8: S002 | C8: al-like | D8: B1 | E8: 1 | F8: al-like_B1_P1_01 | G8: GAGGAGGGCAGCAAACGGAAGTCGTCTTTCGGTGGTTCTGATAGC | H8: al-like_B1_P2_01 | I8: GGAGAGTTCTGGAGTAGTTCGAGGATAGAAGAGTCTTCCTTTACG | J8: B1_P1 (al_like)_1 | K8: B1_P2 (al_like)_1 | L8: GTCGTCTTTCGGTGGTTCTGATAGC | M8: GGAGAGTTCTGGAGTAGTTCGAGGA | N8: =LEN(L8) -> 25 | O8: =LEN(M8) -> 25 | P8: =IF(N8=0,"",(N8-LEN(SUBSTITUTE(SUBSTITUTE(L8,"G",""),"C","")))/N8) -> 0.52 | Q8: =IF(O8=0,"",(O8-LEN(SUBSTITUTE(SUBSTITUTE(M8,"G",""),"C","")))/O8) -> 0.52 | R8: T027 | S8: Both halves | T8: 6 | U8: template position | V8: Master (Jul 2024); B1 file | X8: Both halves
A9: S002-02 | B9: S002 | C9: al-like | D9: B1 | E9: 2 | F9: al-like_B1_P1_02 | G9: GAGGAGGGCAGCAAACGGAAAGCCTAAAGGTGGTCTTTCCGAAGC | H9: al-like_B1_P2_02 | I9: AGTCATCTGCATCATCGCTGTCAGCTAGAAGAGTCTTCCTTTACG | J9: B1_P1 (al_like)_2 | K9: B1_P2 (al_like)_2 | L9: AGCCTAAAGGTGGTCTTTCCGAAGC | M9: AGTCATCTGCATCATCGCTGTCAGC | N9: =LEN(L9) -> 25 | O9: =LEN(M9) -> 25 | P9: =IF(N9=0,"",(N9-LEN(SUBSTITUTE(SUBSTITUTE(L9,"G",""),"C","")))/N9) -> 0.52 | Q9: =IF(O9=0,"",(O9-LEN(SUBSTITUTE(SUBSTITUTE(M9,"G",""),"C","")))/O9) -> 0.52 | R9: T027 | S9: Both halves | T9: 76 | U9: template position | V9: Master (Jul 2024); B1 file | X9: Both halves
A10: S002-03 | B10: S002 | C10: al-like | D10: B1 | E10: 3 | F10: al-like_B1_P1_03 | G10: GAGGAGGGCAGCAAACGGAAGGGGGGGCCGCACCCCCTAGGTAGG | H10: al-like_B1_P2_03 | I10: GGGTTCGGCATGGACGCGACCGAGGTAGAAGAGTCTTCCTTTACG | J10: B1_P1 (al_like)_3 | K10: B1_P2 (al_like)_3 | L10: GGGGGGGCCGCACCCCCTAGGTAGG | M10: GGGTTCGGCATGGACGCGACCGAGG | N10: =LEN(L10) -> 25 | O10: =LEN(M10) -> 25 | P10: =IF(N10=0,"",(N10-LEN(SUBSTITUTE(SUBSTITUTE(L10,"G",""),"C","")))/N10) -> 0.8 | Q10: =IF(O10=0,"",(O10-LEN(SUBSTITUTE(SUBSTITUTE(M10,"G",""),"C","")))/O10) -> 0.72 | R10: T027 | S10: Both halves | T10: 356 | U10: template position | V10: Master (Jul 2024); B1 file | X10: Both halves
A11: S002-04 | B11: S002 | C11: al-like | D11: B1 | E11: 4 | F11: al-like_B1_P1_04 | G11: GAGGAGGGCAGCAAACGGAAAGGCCCGCTAGCAGCGAATGAAAGG | H11: al-like_B1_P2_04 | I11: TCAGGAGACTGTCGGGGGGGTGCTGTAGAAGAGTCTTCCTTTACG | J11: B1_P1 (al_like)_4 | K11: B1_P2 (al_like)_4 | L11: AGGCCCGCTAGCAGCGAATGAAAGG | M11: TCAGGAGACTGTCGGGGGGGTGCTG | N11: =LEN(L11) -> 25 | O11: =LEN(M11) -> 25 | P11: =IF(N11=0,"",(N11-LEN(SUBSTITUTE(SUBSTITUTE(L11,"G",""),"C","")))/N11) -> 0.6 | Q11: =IF(O11=0,"",(O11-LEN(SUBSTITUTE(SUBSTITUTE(M11,"G",""),"C","")))/O11) -> 0.68 | R11: T027 | S11: Both halves | T11: 566 | U11: template position | V11: Master (Jul 2024); B1 file | X11: Both halves
A12: S003-01 | B12: S003 | C12: APC | D12: B1 | E12: 1 | F12: APC_B1_P1_01 | G12: GAGGAGGGCAGCAAACGGAAAGAGTCCATACTGCTCCAGGTATCT | H12: APC_B1_P2_01 | I12: TCCGGAGTCAGTCAATGGAGAATTATAGAAGAGTCTTCCTTTACG | J12: B1_P1 (APC)_1 | K12: B1_P2 (APC)_1 | L12: AGAGTCCATACTGCTCCAGGTATCT | M12: TCCGGAGTCAGTCAATGGAGAATTA | N12: =LEN(L12) -> 25 | O12: =LEN(M12) -> 25 | P12: =IF(N12=0,"",(N12-LEN(SUBSTITUTE(SUBSTITUTE(L12,"G",""),"C","")))/N12) -> 0.48 | Q12: =IF(O12=0,"",(O12-LEN(SUBSTITUTE(SUBSTITUTE(M12,"G",""),"C","")))/O12) -> 0.44 | R12: T076 | S12: Both halves | T12: 6 | U12: template position | V12: Master (Jul 2024); B1 file | X12: P2 only
A13: S003-02 | B13: S003 | C13: APC | D13: B1 | E13: 2 | F13: APC_B1_P1_02 | G13: GAGGAGGGCAGCAAACGGAAGTTCATTGGACGTGGAAGGGGGGCA | H13: APC_B1_P2_02 | I13: AAGAGGCCTGTACAGGCCTCCGGGGTAGAAGAGTCTTCCTTTACG | J13: B1_P1 (APC)_2 | K13: B1_P2 (APC)_2 | L13: GTTCATTGGACGTGGAAGGGGGGCA | M13: AAGAGGCCTGTACAGGCCTCCGGGG | N13: =LEN(L13) -> 25 | O13: =LEN(M13) -> 25 | P13: =IF(N13=0,"",(N13-LEN(SUBSTITUTE(SUBSTITUTE(L13,"G",""),"C","")))/N13) -> 0.6 | Q13: =IF(O13=0,"",(O13-LEN(SUBSTITUTE(SUBSTITUTE(M13,"G",""),"C","")))/O13) -> 0.68 | R13: T076 | S13: Both halves | T13: 76 | U13: template position | V13: Master (Jul 2024); B1 file | X13: Both halves
... A93: S014-10 | B93: S014 | C93: dpp | D93: B1 | E93: 10 | F93: dpp_B1_P1_10 | G93: GAGGAGGGCAGCAAACGGAAATATAACATAGATATAGATGAGAGT | H93: dpp_B1_P2_10 | I93: AAGCACCACATTGTTCACTTCGTCCTAGAAGAGTCTTCCTTTACG | J93: Dpp10_HCR_P1B1 | K93: Dpp10_HCR_P2B1 | L93: ATATAACATAGATATAGATGAGAGT | M93: AAGCACCACATTGTTCACTTCGTCC | N93: =LEN(L93) -> 25 | O93: =LEN(M93) -> 25 | P93: =IF(N93=0,"",(N93-LEN(SUBSTITUTE(SUBSTITUTE(L93,"G",""),"C","")))/N93) -> 0.24 | Q93: =IF(O93=0,"",(O93-LEN(SUBSTITUTE(SUBSTITUTE(M93,"G",""),"C","")))/O93) -> 0.48 | R93: T005 | S93: Both halves | T93: 724 | U93: template position | V93: Master (Jul 2024); B1 file | X93: Both halves
A94: S015-01 | B94: S015 | C94: ds | D94: B1 | E94: 1 | F94: ds_B1_P1_01 | G94: GAGGAGGGCAGCAAACGGAACACTCGTCTGGTATTCGTTCTCGAG | H94: ds_B1_P2_01 | I94: GCGTACCGGGAGCTGCGGCCTCCGGTAGAAGAGTCTTCCTTTACG | J94: ds_dsx_ets5_ | K94: ds_dsx_ets5_ | L94: CACTCGTCTGGTATTCGTTCTCGAG | M94: GCGTACCGGGAGCTGCGGCCTCCGG | N94: =LEN(L94) -> 25 | O94: =LEN(M94) -> 25 | P94: =IF(N94=0,"",(N94-LEN(SUBSTITUTE(SUBSTITUTE(L94,"G",""),"C","")))/N94) -> 0.52 | Q94: =IF(O94=0,"",(O94-LEN(SUBSTITUTE(SUBSTITUTE(M94,"G",""),"C","")))/O94) -> 0.8 | R94: T190 | S94: Both halves | T94: 1327 | U94: template position | V94: ds_dsx_ets5 oPool | W94: ds_dsx_ets5 oPool | X94: Both halves
A95: S015-02 | B95: S015 | C95: ds | D95: B1 | E95: 2 | F95: ds_B1_P1_02 | G95: GAGGAGGGCAGCAAACGGAAGATGTCGGAATTATCTCCTTCATCC | H95: ds_B1_P2_02 | I95: CTGCGGTGTTGGAAGCAAGGAATACTAGAAGAGTCTTCCTTTACG | J95: ds_dsx_ets5_ | K95: ds_dsx_ets5_ | L95: GATGTCGGAATTATCTCCTTCATCC | M95: CTGCGGTGTTGGAAGCAAGGAATAC | N95: =LEN(L95) -> 25 | O95: =LEN(M95) -> 25 | P95: =IF(N95=0,"",(N95-LEN(SUBSTITUTE(SUBSTITUTE(L95,"G",""),"C","")))/N95) -> 0.44 | Q95: =IF(O95=0,"",(O95-LEN(SUBSTITUTE(SUBSTITUTE(M95,"G",""),"C","")))/O95) -> 0.52 | R95: T190 | S95: Both halves | T95: 1407 | U95: template position | V95: ds_dsx_ets5 oPool | W95: ds_dsx_ets5 oPool | X95: Both halves
A96: S015-03 | B96: S015 | C96: ds | D96: B1 | E96: 3 | F96: ds_B1_P1_03 | G96: GAGGAGGGCAGCAAACGGAACGGGACCGGGTTGTTACCAGACCAG | H96: ds_B1_P2_03 | I96: GGCATCGGATTCGTTTCACAATCAATAGAAGAGTCTTCCTTTACG | J96: ds_dsx_ets5_ | K96: ds_dsx_ets5_ | L96: CGGGACCGGGTTGTTACCAGACCAG | M96: GGCATCGGATTCGTTTCACAATCAA | N96: =LEN(L96) -> 25 | O96: =LEN(M96) -> 25 | P96: =IF(N96=0,"",(N96-LEN(SUBSTITUTE(SUBSTITUTE(L96,"G",""),"C","")))/N96) -> 0.64 | Q96: =IF(O96=0,"",(O96-LEN(SUBSTITUTE(SUBSTITUTE(M96,"G",""),"C","")))/O96) -> 0.44 | R96: T190 | S96: Both halves | T96: 1487 | U96: template position | V96: ds_dsx_ets5 oPool | W96: ds_dsx_ets5 oPool | X96: Both halves
A97: S015-04 | B97: S015 | C97: ds | D97: B1 | E97: 4 | F97: ds_B1_P1_04 | G97: GAGGAGGGCAGCAAACGGAACGGTGGACGACAGCGGAGGATTGCC | H97: ds_B1_P2_04 | I97: CATCTAACACTGTCACTAACAACGTTAGAAGAGTCTTCCTTTACG | J97: ds_dsx_ets5_ | K97: ds_dsx_ets5_ | L97: CGGTGGACGACAGCGGAGGATTGCC | M97: CATCTAACACTGTCACTAACAACGT | N97: =LEN(L97) -> 25 | O97: =LEN(M97) -> 25 | P97: =IF(N97=0,"",(N97-LEN(SUBSTITUTE(SUBSTITUTE(L97,"G",""),"C","")))/N97) -> 0.68 | Q97: =IF(O97=0,"",(O97-LEN(SUBSTITUTE(SUBSTITUTE(M97,"G",""),"C","")))/O97) -> 0.4 | R97: T190 | S97: Both halves | T97: 1567 | U97: template position | V97: ds_dsx_ets5 oPool | W97: ds_dsx_ets5 oPool | X97: Both halves
A98: S015-05 | B98: S015 | C98: ds | D98: B1 | E98: 5 | F98: ds_B1_P1_05 | G98: GAGGAGGGCAGCAAACGGAAGGAGACGGTCACGTTGTAGAAGGAC | H98: ds_B1_P2_05 | I98: AATACAGCTGCCGACAGCCTCATTCTAGAAGAGTCTTCCTTTACG | J98: ds_dsx_ets5_ | K98: ds_dsx_ets5_ | L98: GGAGACGGTCACGTTGTAGAAGGAC | M98: AATACAGCTGCCGACAGCCTCATTC | N98: =LEN(L98) -> 25 | O98: =LEN(M98) -> 25 | P98: =IF(N98=0,"",(N98-LEN(SUBSTITUTE(SUBSTITUTE(L98,"G",""),"C","")))/N98) -> 0.56 | Q98: =IF(O98=0,"",(O98-LEN(SUBSTITUTE(SUBSTITUTE(M98,"G",""),"C","")))/O98) -> 0.52 | R98: T190 | S98: Both halves | T98: 1647 | U98: template position | V98: ds_dsx_ets5 oPool | W98: ds_dsx_ets5 oPool | X98: Both halves
A99: S015-06 | B99: S015 | C99: ds | D99: B1 | E99: 6 | F99: ds_B1_P1_06 | G99: GAGGAGGGCAGCAAACGGAATAGTTCACTATCGCGTTCACGCCGC | H99: ds_B1_P2_06 | I99: GGTCGAGCCAGTCCATCGCCCAGGGTAGAAGAGTCTTCCTTTACG | J99: ds_dsx_ets5_ | K99: ds_dsx_ets5_ | L99: TAGTTCACTATCGCGTTCACGCCGC | M99: GGTCGAGCCAGTCCATCGCCCAGGG | N99: =LEN(L99) -> 25 | O99: =LEN(M99) -> 25 | P99: =IF(N99=0,"",(N99-LEN(SUBSTITUTE(SUBSTITUTE(L99,"G",""),"C","")))/N99) -> 0.56 | Q99: =IF(O99=0,"",(O99-LEN(SUBSTITUTE(SUBSTITUTE(M99,"G",""),"C","")))/O99) -> 0.72 | R99: T190 | S99: Both halves | T99: 1727 | U99: template position | V99: ds_dsx_ets5 oPool | W99: ds_dsx_ets5 oPool | X99: Both halves
A100: S015-07 | B100: S015 | C100: ds | D100: B1 | E100: 7 | F100: ds_B1_P1_07 | G100: GAGGAGGGCAGCAAACGGAACCAAGGGGGCAGAAACGCAAAGATC | H100: ds_B1_P2_07 | I100: ACTCAAAATCGCTAGTTGTCTCGTGTAGAAGAGTCTTCCTTTACG | J100: ds_dsx_ets5_ | K100: ds_dsx_ets5_ | L100: CCAAGGGGGCAGAAACGCAAAGATC | M100: ACTCAAAATCGCTAGTTGTCTCGTG | N100: =LEN(L100) -> 25 | O100: =LEN(M100) -> 25 | P100: =IF(N100=0,"",(N100-LEN(SUBSTITUTE(SUBSTITUTE(L100,"G",""),"C","")))/N100) -> 0.56 | Q100: =IF(O100=0,"",(O100-LEN(SUBSTITUTE(SUBSTITUTE(M100,"G",""),"C","")))/O100) -> 0.44 | R100: T190 | S100: Both halves | T100: 1807 | U100: template position | V100: ds_dsx_ets5 oPool | W100: ds_dsx_ets5 oPool | X100: Both halves
A101: S015-08 | B101: S015 | C101: ds | D101: B1 | E101: 8 | F101: ds_B1_P1_08 | G101: GAGGAGGGCAGCAAACGGAACTTCACCATTGCGGTCGTGGACAGG | H101: ds_B1_P2_08 | I101: GTTGTCGTTTATATCGAGAAGTTGGTAGAAGAGTCTTCCTTTACG | J101: ds_dsx_ets5_ | K101: ds_dsx_ets5_ | L101: CTTCACCATTGCGGTCGTGGACAGG | M101: GTTGTCGTTTATATCGAGAAGTTGG | N101: =LEN(L101) -> 25 | O101: =LEN(M101) -> 25 | P101: =IF(N101=0,"",(N101-LEN(SUBSTITUTE(SUBSTITUTE(L101,"G",""),"C","")))/N101) -> 0.6 | Q101: =IF(O101=0,"",(O101-LEN(SUBSTITUTE(SUBSTITUTE(M101,"G",""),"C","")))/O101) -> 0.4 | R101: T190 | S101: Both halves | T101: 1887 | U101: template position | V101: ds_dsx_ets5 oPool | W101: ds_dsx_ets5 oPool | X101: Both halves
A102: S015-09 | B102: S015 | C102: ds | D102: B1 | E102: 9 | F102: ds_B1_P1_09 | G102: GAGGAGGGCAGCAAACGGAAATCCTCCCCTCCTTCAGAGAGACGT | H102: ds_B1_P2_09 | I102: ACAGCTACTATGGGCTCGTTGCTAGTAGAAGAGTCTTCCTTTACG | J102: ds_dsx_ets5_ | K102: ds_dsx_ets5_ | L102: ATCCTCCCCTCCTTCAGAGAGACGT | M102: ACAGCTACTATGGGCTCGTTGCTAG | N102: =LEN(L102) -> 25 | O102: =LEN(M102) -> 25 | P102: =IF(N102=0,"",(N102-LEN(SUBSTITUTE(SUBSTITUTE(L102,"G",""),"C","")))/N102) -> 0.56 | Q102: =IF(O102=0,"",(O102-LEN(SUBSTITUTE(SUBSTITUTE(M102,"G",""),"C","")))/O102) -> 0.52 | R102: T190 | S102: Both halves | T102: 1967 | U102: template position | V102: ds_dsx_ets5 oPool | W102: ds_dsx_ets5 oPool | X102: Both halves
A103: S015-10 | B103: S015 | C103: ds | D103: B1 | E103: 10 | F103: ds_B1_P1_10 | G103: GAGGAGGGCAGCAAACGGAACTATTCTGTACGTAACTGTTCCGAA | H103: ds_B1_P2_10 | I103: GGAATACATCGTTGTCGTTCCCATTTAGAAGAGTCTTCCTTTACG | J103: ds_dsx_ets5_ | K103: ds_dsx_ets5_ | L103: CTATTCTGTACGTAACTGTTCCGAA | M103: GGAATACATCGTTGTCGTTCCCATT | N103: =LEN(L103) -> 25 | O103: =LEN(M103) -> 25 | P103: =IF(N103=0,"",(N103-LEN(SUBSTITUTE(SUBSTITUTE(L103,"G",""),"C","")))/N103) -> 0.4 | Q103: =IF(O103=0,"",(O103-LEN(SUBSTITUTE(SUBSTITUTE(M103,"G",""),"C","")))/O103) -> 0.44 | R103: T190 | S103: Both halves | T103: 2047 | U103: template position | V103: ds_dsx_ets5 oPool | W103: ds_dsx_ets5 oPool | X103: Both halves
A104: S016-01 | B104: S016 | C104: dscam2 | D104: B1 | E104: 1 | F104: dscam2_B1_P1_01 | G104: GAGGAGGGCAGCAAACGGAAACCGGGATCTTATCACTAATCCCGG | H104: dscam2_B1_P2_01 | I104: AACTGTGTACCATAATCCCGCTTGTTAGAAGAGTCTTCCTTTACG | J104: B1_P1 (dscam2)_1 | K104: B1_P2 (dscam2)_1 | L104: ACCGGGATCTTATCACTAATCCCGG | M104: AACTGTGTACCATAATCCCGCTTGT | N104: =LEN(L104) -> 25 | O104: =LEN(M104) -> 25 | P104: =IF(N104=0,"",(N104-LEN(SUBSTITUTE(SUBSTITUTE(L104,"G",""),"C","")))/N104) -> 0.52 | Q104: =IF(O104=0,"",(O104-LEN(SUBSTITUTE(SUBSTITUTE(M104,"G",""),"C","")))/O104) -> 0.44 | R104: T042 | S104: Both halves | T104: 146 | U104: template position | V104: Master (Jul 2024); B1 file | X104: Both halves
A105: S016-02 | B105: S016 | C105: dscam2 | D105: B1 | E105: 2 | F105: dscam2_B1_P1_02 | G105: GAGGAGGGCAGCAAACGGAATGACCTAGACTTTCTTACATTTTGC | H105: dscam2_B1_P2_02 | I105: TTTTCTTTTAGTTTTCTTGTGATCGTAGAAGAGTCTTCCTTTACG | J105: B1_P1 (dscam2)_2 | K105: B1_P2 (dscam2)_2 | L105: TGACCTAGACTTTCTTACATTTTGC | M105: TTTTCTTTTAGTTTTCTTGTGATCG | N105: =LEN(L105) -> 25 | O105: =LEN(M105) -> 25 | P105: =IF(N105=0,"",(N105-LEN(SUBSTITUTE(SUBSTITUTE(L105,"G",""),"C","")))/N105) -> 0.36 | Q105: =IF(O105=0,"",(O105-LEN(SUBSTITUTE(SUBSTITUTE(M105,"G",""),"C","")))/O105) -> 0.28 | R105: T042 | S105: Both halves | T105: 216 | U105: template position | V105: Master (Jul 2024); B1 file | X105: Both halves
A106: S016-03 | B106: S016 | C106: dscam2 | D106: B1 | E106: 3 | F106: dscam2_B1_P1_03 | G106: GAGGAGGGCAGCAAACGGAATTGTACCAATTGTCACGGTCTGCAA | H106: dscam2_B1_P2_03 | I106: TCCCTGAACTTAGATCCCTTTTAAATAGAAGAGTCTTCCTTTACG | J106: B1_P1 (dscam2)_3 | K106: B1_P2 (dscam2)_3 | L106: TTGTACCAATTGTCACGGTCTGCAA | M106: TCCCTGAACTTAGATCCCTTTTAAA | N106: =LEN(L106) -> 25 | O106: =LEN(M106) -> 25 | P106: =IF(N106=0,"",(N106-LEN(SUBSTITUTE(SUBSTITUTE(L106,"G",""),"C","")))/N106) -> 0.44 | Q106: =IF(O106=0,"",(O106-LEN(SUBSTITUTE(SUBSTITUTE(M106,"G",""),"C","")))/O106) -> 0.36 | R106: T042 | S106: Both halves | T106: 286 | U106: template position | V106: Master (Jul 2024); B1 file | X106: Both halves
A107: S016-04 | B107: S016 | C107: dscam2 | D107: B1 | E107: 4 | F107: dscam2_B1_P1_04 | G107: GAGGAGGGCAGCAAACGGAAGGCGATAAAACTTTATCGTTGAAAT | H107: dscam2_B1_P2_04 | I107: GTACATTGAAGACTAATGTCTTCACTAGAAGAGTCTTCCTTTACG | J107: B1_P1 (dscam2)_4 | K107: B1_P2 (dscam2)_4 | L107: GGCGATAAAACTTTATCGTTGAAAT | M107: GTACATTGAAGACTAATGTCTTCAC | N107: =LEN(L107) -> 25 | O107: =LEN(M107) -> 25 | P107: =IF(N107=0,"",(N107-LEN(SUBSTITUTE(SUBSTITUTE(L107,"G",""),"C","")))/N107) -> 0.32 | Q107: =IF(O107=0,"",(O107-LEN(SUBSTITUTE(SUBSTITUTE(M107,"G",""),"C","")))/O107) -> 0.36 | R107: T042 | S107: Both halves | T107: 356 | U107: template position | V107: Master (Jul 2024); B1 file | X107: Both halves
A108: S016-05 | B108: S016 | C108: dscam2 | D108: B1 | E108: 5 | F108: dscam2_B1_P1_05 | G108: GAGGAGGGCAGCAAACGGAAATCCCTCTCCCAAATGAACCGCGGT | H108: dscam2_B1_P2_05 | I108: GTCAGTATTTGACGTGATGACTACATAGAAGAGTCTTCCTTTACG | J108: B1_P1 (dscam2)_5 | K108: B1_P2 (dscam2)_5 | L108: ATCCCTCTCCCAAATGAACCGCGGT | M108: GTCAGTATTTGACGTGATGACTACA | N108: =LEN(L108) -> 25 | O108: =LEN(M108) -> 25 | P108: =IF(N108=0,"",(N108-LEN(SUBSTITUTE(SUBSTITUTE(L108,"G",""),"C","")))/N108) -> 0.56 | Q108: =IF(O108=0,"",(O108-LEN(SUBSTITUTE(SUBSTITUTE(M108,"G",""),"C","")))/O108) -> 0.4 | R108: T042 | S108: Both halves | T108: 426 | U108: template position | V108: Master (Jul 2024); B1 file | X108: Both halves
A109: S016-06 | B109: S016 | C109: dscam2 | D109: B1 | E109: 6 | F109: dscam2_B1_P1_06 | G109: GAGGAGGGCAGCAAACGGAACGATCCCCGTCGGTGACATCATTTG | H109: dscam2_B1_P2_06 | I109: TGGATATGTTTAATTGTGATATTACTAGAAGAGTCTTCCTTTACG | J109: B1_P1 (dscam2)_6 | K109: B1_P2 (dscam2)_6 | L109: CGATCCCCGTCGGTGACATCATTTG | M109: TGGATATGTTTAATTGTGATATTAC | N109: =LEN(L109) -> 25 | O109: =LEN(M109) -> 25 | P109: =IF(N109=0,"",(N109-LEN(SUBSTITUTE(SUBSTITUTE(L109,"G",""),"C","")))/N109) -> 0.56 | Q109: =IF(O109=0,"",(O109-LEN(SUBSTITUTE(SUBSTITUTE(M109,"G",""),"C","")))/O109) -> 0.24 | R109: T042 | S109: Both halves | T109: 496 | U109: template position | V109: Master (Jul 2024); B1 file | X109: Both halves
A110: S017-01 | B110: S017 | C110: e20m | D110: B1 | E110: 1 | F110: e20m_B1_P1_01 | G110: GAGGAGGGCAGCAAACGGAACATTCTATAACGACTCCAGAACAGC | H110: e20m_B1_P2_01 | I110: GTCTTCATACGCTTCGTGTAGTTTGTAGAAGAGTCTTCCTTTACG | J110: B1_P1 (e20m)_1 | K110: B1_P2 (e20m)_1 | L110: CATTCTATAACGACTCCAGAACAGC | M110: GTCTTCATACGCTTCGTGTAGTTTG | N110: =LEN(L110) -> 25 | O110: =LEN(M110) -> 25 | P110: =IF(N110=0,"",(N110-LEN(SUBSTITUTE(SUBSTITUTE(L110,"G",""),"C","")))/N110) -> 0.44 | Q110: =IF(O110=0,"",(O110-LEN(SUBSTITUTE(SUBSTITUTE(M110,"G",""),"C","")))/O110) -> 0.44 | R110: T033 | S110: Both halves | T110: 216 | U110: template position | V110: Master (Jul 2024); B1 file | X110: Both halves
A111: S017-02 | B111: S017 | C111: e20m | D111: B1 | E111: 2 | F111: e20m_B1_P1_02 | G111: GAGGAGGGCAGCAAACGGAACTGGAGTCACCTCGGCGAACACTGG | H111: e20m_B1_P2_02 | I111: CAGCGATGGAGACGACGAGGGCGCCTAGAAGAGTCTTCCTTTACG | J111: B1_P1 (e20m)_2 | K111: B1_P2 (e20m)_2 | L111: CTGGAGTCACCTCGGCGAACACTGG | M111: CAGCGATGGAGACGACGAGGGCGCC | N111: =LEN(L111) -> 25 | O111: =LEN(M111) -> 25 | P111: =IF(N111=0,"",(N111-LEN(SUBSTITUTE(SUBSTITUTE(L111,"G",""),"C","")))/N111) -> 0.64 | Q111: =IF(O111=0,"",(O111-LEN(SUBSTITUTE(SUBSTITUTE(M111,"G",""),"C","")))/O111) -> 0.72 | R111: T033 | S111: Both halves | T111: 286 | U111: template position | V111: Master (Jul 2024); B1 file | X111: Both halves
A112: S017-03 | B112: S017 | C112: e20m | D112: B1 | E112: 3 | F112: e20m_B1_P1_03 | G112: GAGGAGGGCAGCAAACGGAACTCTTCGCTGGTGTTCGCAGCACAG | H112: e20m_B1_P2_03 | I112: ACGATTTCAGTGGGGGGTCGATAAGTAGAAGAGTCTTCCTTTACG | J112: B1_P1 (e20m)_3 | K112: B1_P2 (e20m)_3 | L112: CTCTTCGCTGGTGTTCGCAGCACAG | M112: ACGATTTCAGTGGGGGGTCGATAAG | N112: =LEN(L112) -> 25 | O112: =LEN(M112) -> 25 | P112: =IF(N112=0,"",(N112-LEN(SUBSTITUTE(SUBSTITUTE(L112,"G",""),"C","")))/N112) -> 0.6 | Q112: =IF(O112=0,"",(O112-LEN(SUBSTITUTE(SUBSTITUTE(M112,"G",""),"C","")))/O112) -> 0.52 | R112: T033 | S112: Both halves | T112: 356 | U112: template position | V112: Master (Jul 2024); B1 file | X112: Both halves
A113: S017-04 | B113: S017 | C113: e20m | D113: B1 | E113: 4 | F113: e20m_B1_P1_04 | G113: GAGGAGGGCAGCAAACGGAAAGTAGAGGCATATCTATCAGGCCTC | H113: e20m_B1_P2_04 | I113: TTTCTCTCCTTGTTCATTAACAAGTTAGAAGAGTCTTCCTTTACG | J113: B1_P1 (e20m)_4 | K113: B1_P2 (e20m)_4 | L113: AGTAGAGGCATATCTATCAGGCCTC | M113: TTTCTCTCCTTGTTCATTAACAAGT | N113: =LEN(L113) -> 25 | O113: =LEN(M113) -> 25 | P113: =IF(N113=0,"",(N113-LEN(SUBSTITUTE(SUBSTITUTE(L113,"G",""),"C","")))/N113) -> 0.48 | Q113: =IF(O113=0,"",(O113-LEN(SUBSTITUTE(SUBSTITUTE(M113,"G",""),"C","")))/O113) -> 0.32 | R113: T033 | S113: Both halves | T113: 426 | U113: template position | V113: Master (Jul 2024); B1 file | X113: Both halves
A114: S017-05 | B114: S017 | C114: e20m | D114: B1 | E114: 5 | F114: e20m_B1_P1_05 | G114: GAGGAGGGCAGCAAACGGAAGACTGGTCAACTCGCTGGTGAGATG | H114: e20m_B1_P2_05 | I114: CAGGAATGAACCCTTGGATGGTGTGTAGAAGAGTCTTCCTTTACG | J114: B1_P1 (e20m)_5 | K114: B1_P2 (e20m)_5 | L114: GACTGGTCAACTCGCTGGTGAGATG | M114: CAGGAATGAACCCTTGGATGGTGTG | N114: =LEN(L114) -> 25 | O114: =LEN(M114) -> 25 | P114: =IF(N114=0,"",(N114-LEN(SUBSTITUTE(SUBSTITUTE(L114,"G",""),"C","")))/N114) -> 0.56 | Q114: =IF(O114=0,"",(O114-LEN(SUBSTITUTE(SUBSTITUTE(M114,"G",""),"C","")))/O114) -> 0.52 | R114: T033 | S114: Both halves | T114: 496 | U114: template position | V114: Master (Jul 2024); B1 file | X114: Both halves
A115: S017-06 | B115: S017 | C115: e20m | D115: B1 | E115: 6 | F115: e20m_B1_P1_06 | G115: GAGGAGGGCAGCAAACGGAACCCTTCAGCAAGTTGAGGAAGTCAT | H115: e20m_B1_P2_06 | I115: TAGACGGTGCCGTCTGGCCTGCGACTAGAAGAGTCTTCCTTTACG | J115: B1_P1 (e20m)_6 | K115: B1_P2 (e20m)_6 | L115: CCCTTCAGCAAGTTGAGGAAGTCAT | M115: TAGACGGTGCCGTCTGGCCTGCGAC | N115: =LEN(L115) -> 25 | O115: =LEN(M115) -> 25 | P115: =IF(N115=0,"",(N115-LEN(SUBSTITUTE(SUBSTITUTE(L115,"G",""),"C","")))/N115) -> 0.48 | Q115: =IF(O115=0,"",(O115-LEN(SUBSTITUTE(SUBSTITUTE(M115,"G",""),"C","")))/O115) -> 0.68 | R115: T033 | S115: Both halves | T115: 566 | U115: template position | V115: Master (Jul 2024); B1 file | X115: Both halves
... A148: S022-06 | B148: S022 | C148: gasp1 | D148: B1 | E148: 6 | F148: gasp1_B1_P1_06 | G148: GAGGAGGGCAGCAAACGGAAGGAGTTTAGGCATTTGTTGGAGCAC | H148: gasp1_B1_P2_06 | I148: TTTCTCCTGCTTGCGAAGAATTTGTTAGAAGAGTCTTCCTTTACG | J148: B1_P1 (gasp1)_6 | K148: B1_P2 (gasp1)_6 | L148: GGAGTTTAGGCATTTGTTGGAGCAC | M148: TTTCTCCTGCTTGCGAAGAATTTGT | N148: =LEN(L148) -> 25 | O148: =LEN(M148) -> 25 | P148: =IF(N148=0,"",(N148-LEN(SUBSTITUTE(SUBSTITUTE(L148,"G",""),"C","")))/N148) -> 0.48 | Q148: =IF(O148=0,"",(O148-LEN(SUBSTITUTE(SUBSTITUTE(M148,"G",""),"C","")))/O148) -> 0.4 | R148: T035 | S148: Both halves | T148: 426 | U148: template position | V148: Master (Jul 2024); B1 file | X148: Both halves
A149: S023-01 | B149: S023 | C149: GFP | D149: B1 | E149: 1 | F149: GFP_B1_P1_01 | G149: GAGGAGGGCAGCAAACGGAACACGCTGAACTTGTGGCCGTTTAC | H149: GFP_B1_P2_01 | I149: GGTGGCATCGCCCTCGCCCTCGCCGTAGAAGAGTCTTCCTTTACG | J149: gfp1_HCR_P1B1 | K149: gfp1_HCR_P2B1 | L149: CACGCTGAACTTGTGGCCGTTTAC | M149: GGTGGCATCGCCCTCGCCCTCGCCG | N149: =LEN(L149) -> 24 | O149: =LEN(M149) -> 25 | P149: =IF(N149=0,"",(N149-LEN(SUBSTITUTE(SUBSTITUTE(L149,"G",""),"C","")))/N149) -> 0.54166667 | Q149: =IF(O149=0,"",(O149-LEN(SUBSTITUTE(SUBSTITUTE(M149,"G",""),"C","")))/O149) -> 0.8 | R149: T023 | S149: Both halves | T149: 67 | U149: probe name | V149: Master (Jul 2024); B1 file | Y149: P1 arm 24 nt
A150: S023-02 | B150: S023 | C150: GFP | D150: B1 | E150: 2 | F150: GFP_B1_P1_02 | G150: GAGGAGGGCAGCAAACGGAAGTGCAGATGAACTTCAGGGTCAGCT | H150: GFP_B1_P2_02 | I150: GGCCAGGGCACGGGCAGCTTGCCGGTAGAAGAGTCTTCCTTTACG | J150: gfp2_HCR_P1B1 | K150: gfp2_HCR_P2B1 | L150: GTGCAGATGAACTTCAGGGTCAGCT | M150: GGCCAGGGCACGGGCAGCTTGCCGG | N150: =LEN(L150) -> 25 | O150: =LEN(M150) -> 25 | P150: =IF(N150=0,"",(N150-LEN(SUBSTITUTE(SUBSTITUTE(L150,"G",""),"C","")))/N150) -> 0.52 | Q150: =IF(O150=0,"",(O150-LEN(SUBSTITUTE(SUBSTITUTE(M150,"G",""),"C","")))/O150) -> 0.8 | R150: T023 | S150: Both halves | T150: 125 | U150: template position | V150: Master (Jul 2024); B1 file
A151: S023-03 | B151: S023 | C151: GFP | D151: B1 | E151: 3 | F151: GFP_B1_P1_03 | G151: GAGGAGGGCAGCAAACGGAAGGCATGGCGGACTTGAAGAAGTCGT | H151: GFP_B1_P2_03 | I151: ATGGTGCGCTCCTGGACGTAGCCTTTAGAAGAGTCTTCCTTTACG | J151: gfp3_HCR_P1B1 | K151: gfp3_HCR_P2B1 | L151: GGCATGGCGGACTTGAAGAAGTCGT | M151: ATGGTGCGCTCCTGGACGTAGCCTT | N151: =LEN(L151) -> 25 | O151: =LEN(M151) -> 25 | P151: =IF(N151=0,"",(N151-LEN(SUBSTITUTE(SUBSTITUTE(L151,"G",""),"C","")))/N151) -> 0.56 | Q151: =IF(O151=0,"",(O151-LEN(SUBSTITUTE(SUBSTITUTE(M151,"G",""),"C","")))/O151) -> 0.6 | R151: T023 | S151: Both halves | T151: 245 | U151: template position | V151: Master (Jul 2024); B1 file
...

Sheet Templates
A1: Template_ID | B1: Gene (short) | C1: Organism | D1: Header as written in source | E1: Source file | F1: Length (nt) | G1: # pairs assigned here | H1: Sequence (sense, 5′→3′)
A2: T001 | B2: shaven | C2: Bicyclus anynana | D2: shaven partial mRNA: | E2: Anupama_scale | F2: =LEN(H2) -> 1061 | G2: =COUNTIF(Probe_Pairs!$R:$R,A2) -> 8 | H2: ACGGTGGAGTCAACCAACTAGGCGGAGTGTTTGTGAATGGGCGACCGTTGCCCGACGTCGTGCGACAGCGGATAGTGGAGCTGGCGCACAGCGGCGTGCGGCCGTGCGACATCAGTCGACAACTACGCGTGTCGCACGGCTGCGTGTCGAAGATACTGTCGCGATACTACGAAACGGGGAGTTTCAAGGCTGGCGTGATAGGCGGGTCGAAGCCCAAGGTAGCGACCCCTCCTGTGGTGGACGCCATAGCTGCATACAAGCGAGAGAACCCCACGATGTTCGCCTGGGAGATCCGGGACAGATTGCTCAGCGAAGGCATTTGCAGCCAGGACAATGTACCCTCAGTATCTAGTATTAATAGGATCGTGCGGAACAAGGCGGCGGAGAAGGCGAAGCACGCGCACAACCAACAGCAGCAGCAAGAACAGGAGATCAGCTCGGCGCAGGGGAGCGTTGTTTCTGTGATAACCCATGCGGGCAACGCGCCTGGTGCCACAGCGGTGCTGACTCCCACCACGGAGCACGTGAACAACGCAGGCAGCTACAGTATCAACGGCATCCTGGGGATCGAGCAGGTGGACCAGCTTCACAACGGCAACCCGCTCAAGAGGAAGCGCCATGAGGACCAGGATGAGAACAGAGACTTCAACAGCCATTCGGAGGACGACGTCAAAAGACAAAGAAGTCATTACAATGGCGACCAAATATACTCCAACCTGTGGTCATCATCGAAGTGGAGCCTGAAGGACGAGTACAAGCTGCTGTCGGAGCTGGGCGGCGGCACGGGCTACTACGGCGAGCTGTTCGACGCGCCCTACGACCATCCCCACCACTACACCCCCCACTCCGCCACCAACGACTCGACGGGCTCCGCGCCGGCGGGCGGTGAGCCCCCGTCGGCGGCGGGCAGTCCCGACGCGGCCGCGCTCGTGGTGCTGCAGCCGCCCGCGCCGCCCTACCCGCCCTACGCGCACTACGACGGCACCGCCACTCTCGCAAGCGAATATGCCTACGCGGCCCCCTACTCGCAGTACTCCCCCTACGGCGGGCCGTACTCGCAC
A3: T002 | B3: senseless | C3: Bicyclus anynana | D3: Senseless mRNA: | E3: Anupama_scale | F3: =LEN(H3) -> 1098 | G3: =COUNTIF(Probe_Pairs!$R:$R,A3) -> 8 | H3: ATGTCCCGCCACGTGCTTCTGTCCCGGCTGGCGGAGCACTTCCAGGCGGCTTCACCCCCCGGCCAGCGGTTCCCGTCGCCGGACAGGAGCGTGTCTCCCCACACGCCCACGTCGCCTCGCTCTCCCCCCCAGTCGCCGGACTCTCTCGCACAGCAGCGCTTGGACCTGCTGCAGCTGGGAGACATTGAGATTGCAGGCCGTGCTCTCAAACAGTACGCCAGGGCTACAGAGCTGGGAGCCTTAATGTACTGCAGCGGGCTGGGCGCACTGTACGGCGGCGCCGGAGTGTGGCCGCTACTGCTGCCGCAAGCGCCACACTTTGCGCCAAGTGATCACGCAAGACATACACCACCCCGAGACGATGATGAAGAAGAGTTACCATTAAACTTATCGACGAAAAATAGACAGATTTGGTCGCCGGGCAGTGCGTGTGAACGTGAGCAAATAGAAACTGAGAGAGAATCGCCAGCGTCGCGTTGGGACGACCGCGAAGATCTAGAACCCCTCGAGCTCGTGAAGAGATGCCGCAGCAGCTCTGATGATGACAGGCTCTCCAGCTCCGAGTCCCGACGCTGTCCGTCAGAGCCGTCCTTCAACACCTACCTACCACCGCCGCCTCAGCCAGACATGAACTTTTCACTCCTTCTCAAGAATGAAAACAAAAATGAAAAATCCTTTCAGTGCAAGCAATGCGGCAAATGCTTCAAGCGCTCCAGCACGCTGTCCACGCATCTGCTCATCCACTCCGACACCAGGCCCTACCCGTGCCAGTACTGCGGGAAACGATTCCACCAGAAGTCCGATATGAAGAAGCACACCTACATACACACAGGTGAAAAGCCGCATAAATGCGTCGTATGCTCTAAAGCCTTCAGCCAAAGTTCGAATCTGATCACGCATATGCGGAAGCACACCGGTTACAAGCCTTTTTCATGCGGGCTATGCGAAAAGGCATTCCAACGTAAAGTTGATCTCCGACGTCACAGGGAGTCCCAGCATGCGGAGGTGGACTCCCCGGCCTGCCCCACCCTACCACGTCACCGCTATACATACTACGGCGAGGAACAAGCTCCGTTAACTCCACTTATCTCTAACTGA
A4: T003 | B4: HR38 | C4: Bicyclus anynana | D4: HR38 partial mRNA: | E4: Anupama_scale | F4: =LEN(H4) -> 1401 | G4: =COUNTIF(Probe_Pairs!$R:$R,A4) -> 8 | H4: CACCAAGGACATGCATCAACACAGCTATTGTATCAATATCATCAACCTGCATTACCTTACGTTCCATCACCCTACTACGCACCCGCTCAGCCGTGCTCCCCGACATTTGATACCGGTGGCGTGACAAATGCGCAAGAAGCATATTCATTGCCACCATTTCCCAGTTCAGTGGATCTACATATATCTTCCGACCAAGGAGCTAGGCAACGAAGATCGTCCTTGCCGGTTCAGAGATCAGAGTCTAGTAGTTCTAACGACAGTCCCAAATTACACGGCAGCAGAATACACTGTATGCAAGCGTCAGCGCCGAGCTCCGCGTCGAGCTCGCCTGGTGGACCTCAGCAAGACAACTCCGGTTCTCGGGCAGCTCCACCATCACCGAGTCAACTCTGTGCTGTTTGTGGAGATACGGCTGCATGTCAACATTACGGAGTGCGAACTTGTGAAGGGTGCAAAGGATTTTTCAAAAGAACTGTCCAAAAAGGTTCTAAATATGTTTGCTTAGCTGAAAAATCGTGTCCAGTGGATAAGAGAAGAAGAAACAGGTGTCAATTTTGTCGGTTTCAGAAGTGTCTTGCTGTAGGAATGGTGAAAGAGGTCGTGCGGACCGATTCGCTTAAAGGGAGACGAGGGAGATTACCGTCAAAACCAAAATGTCCGCAAGAATCACCACCGAGTCCGCCAATCTCTTTAATAACGGCATTAGTCAGAGCGCATGTCGACACGTCTCCTGATTTTGGCAATCTTGATTATTCACAATACAGAGAGCCGAACCCGATGGAAGTACCTATATCGGATTTAGAAGTGATCCAACAATTTTATTCGTTATTGACAACGTCTATCGATATGATAAAAATATTTGCGGAGAAAGTCCCTGGCTTCGGCGAACTTTGCCCTGAAGACCGAGAACAACTGTTCGCATCGGCACGGCTGGAATTGTTCGTCTTGCGTCTCGCCTATCGCACTCGCCCGGAGGACACTAAGCTCACTTTCTGCAATGGATTGGTTCTCGATAAACGACAGTGTCAAAGATCTTTTGGAGACTGGTTGCACGCTGTCCTTGATTTTAGTAATACACTGCACTCTATGGATATTGACATCTCTACTTTTGCCTGCCTGTGTGCATTGGCTCTTATAACAGAGAGACATGGTCTAAAGGAGCCGCACCGAGTTGAGCAGTTGCAAATGAAGATCATCGGATGTCTGCGCGCGCACATGCCCTGCGGCGGCAACACCAACGCCGCCGGGGCGCCGCACTTCAGCCGAGTCCTAGGCGCGCTGCCGGAGCTGCGGTCCCTCTCCGTGCAAGGGCTCCAGCGAATCTTCTACCTGAAGCTCGAGGACTTAGTGCCCGCGCCTCCTCTCATCGAGAACATGTTTCGCGCCAGCCTGCCGTTCTAA
