Workbook

Sheet README
A1: HCR probe sets designed by Jeriel
A2: This file holds one person's HCR probe sets. Every designer has their own file in the data folder of the HCR probe database, all with the same layout, and the probe finder viewer is built from all of them together.
A4: Sheets
A5: Probe_Sets has one row per gene × amplifier set; its pair counts come from Probe_Pairs, which has one row per P1/P2 pair linked by Set_ID. Templates holds target sequences if you have them (optional). Amplifiers is the reference list of initiator and spacer sequences, the same in every file.
A7: Set IDs
A8: Set IDs in this file start with "JL-" so they never clash with other people's files. Pair IDs are the Set_ID plus a two-digit pair number.
A10: Columns for you to fill in
A11: Headers in dark yellow are input columns (Status, Tube / location, Order date, Vendor / order ID, Notes); Status has a drop-down list. The other columns were filled when the file was built and checked: amplifier and P1/P2 were read from each oligo's own initiator, P1 and P2 were paired by position on the genome or template, and binding arms were matched against the NCBI B. anynana CDS (genome_cds.fa). Check notes summarizes anything worth a look; the pair-level detail is in the Pair flag column of Probe_Pairs.
A13: History
A14: Imported from Jeriel_HCRoligosequences.xlsx (one sheet per gene). The "scr CRISPR" sheet (CRISPR primers) and the Zasp sheet (probe names only, no sequences) were not imported. Sheets marked "(did not order)" were entered as Status = Designed. Name to be confirmed with Jeriel.

Sheet Probe_Sets
A1: Set_ID | B1: Designed by | C1: Gene (short) | D1: Gene / protein name | E1: Organism | F1: LOC / GeneID | G1: NCBI accession | H1: Other ID | I1: Amplifier | J1: Fluorophore | K1: # pairs | L1: # pairs verified on template | M1: Same gene also on | N1: Names used in source files | O1: Source files | P1: Template(s) | Q1: LOC source | R1: Genome LOC (genome_cds.fa match) | S1: # pairs verified in genome | T1: Genome confidence | U1: NCBI protein name (genome_cds.fa) | V1: Name in ncbi_annotation_ultimate.csv | W1: XP accession(s) of genome LOC | X1: Check notes | Y1: Status | Z1: Tube / location | AA1: Order date | AB1: Vendor / order ID | AC1: Notes
A2: JL-001 | B2: Jeriel | C2: B-H1 | D2: homeobox protein B-H1-like | E2: Bicyclus anynana | F2: LOC112051348 | I2: B1 | J2: AF546 | K2: =COUNTIF(Probe_Pairs!$B:$B,A2) -> 8 | L2: =COUNTIFS(Probe_Pairs!$B:$B,A2,Probe_Pairs!$S:$S,"Both halves") -> 0 | N2: B-H1, B-H | O2: Jeriel_HCRoligosequences.xlsx | Q2: stated in Jeriel's sheet | R2: LOC112051348 | S2: =IF(R2="","",COUNTIFS(Probe_Pairs!$B:$B,A2,Probe_Pairs!$X:$X,"Both halves")) -> 8 | T2: =IF(R2="","",IF(S2*2>=K2,"High","Low")) -> High | U2: homeobox protein B-H1-like | V2: homeobox protein B-H1-like | W2: XP_023945719.2 | X2: 8 pair(s) flagged in Probe_Pairs
A3: JL-002 | B3: Jeriel | C3: bowel | D3: protein bowel | E3: Bicyclus anynana | F3: LOC112044995 | I3: B1 | J3: AF546 | K3: =COUNTIF(Probe_Pairs!$B:$B,A3) -> 10 | L3: =COUNTIFS(Probe_Pairs!$B:$B,A3,Probe_Pairs!$S:$S,"Both halves") -> 0 | M3: B3 | N3: bowel | O3: Jeriel_HCRoligosequences.xlsx | Q3: stated in Jeriel's sheet | R3: LOC112044995 | S3: =IF(R3="","",COUNTIFS(Probe_Pairs!$B:$B,A3,Probe_Pairs!$X:$X,"Both halves")) -> 10 | T3: =IF(R3="","",IF(S3*2>=K3,"High","Low")) -> High | U3: protein bowel | V3: protein bowel-like | W3: XP_023936788.2
A4: JL-003 | B4: Jeriel | C4: btlfgfr | D4: fibroblast growth factor receptor homolog 1 isoform X1 | E4: Bicyclus anynana | F4: LOC112044537 | I4: B1 | J4: AF546 | K4: =COUNTIF(Probe_Pairs!$B:$B,A4) -> 10 | L4: =COUNTIFS(Probe_Pairs!$B:$B,A4,Probe_Pairs!$S:$S,"Both halves") -> 0 | N4: btl | O4: Jeriel_HCRoligosequences.xlsx | Q4: stated in Jeriel's sheet | R4: LOC112044537 | S4: =IF(R4="","",COUNTIFS(Probe_Pairs!$B:$B,A4,Probe_Pairs!$X:$X,"Both halves")) -> 10 | T4: =IF(R4="","",IF(S4*2>=K4,"High","Low")) -> High | U4: fibroblast growth factor receptor homolog 1 isoform X1 | V4: fibroblast growth factor receptor homolog 1-like isoform X1 | W4: XP_023936187.2; XP_023936186.2
A5: JL-004 | B5: Jeriel | C5: diaphanous | D5: protein diaphanous | E5: Bicyclus anynana | F5: LOC112052023 | I5: B1 | J5: AF546 | K5: =COUNTIF(Probe_Pairs!$B:$B,A5) -> 8 | L5: =COUNTIFS(Probe_Pairs!$B:$B,A5,Probe_Pairs!$S:$S,"Both halves") -> 0 | N5: dia | O5: Jeriel_HCRoligosequences.xlsx | Q5: stated in Jeriel's sheet | R5: LOC112052023 | S5: =IF(R5="","",COUNTIFS(Probe_Pairs!$B:$B,A5,Probe_Pairs!$X:$X,"Both halves")) -> 8 | T5: =IF(R5="","",IF(S5*2>=K5,"High","Low")) -> High | U5: protein diaphanous | V5: protein diaphanous isoform X1 | W5: XP_052738807.1
A6: JL-005 | B6: Jeriel | C6: distal-less | D6: homeotic protein distal-less isoform X1 | E6: Bicyclus anynana | F6: LOC112055223 | I6: B1 | J6: AF546 | K6: =COUNTIF(Probe_Pairs!$B:$B,A6) -> 12 | L6: =COUNTIFS(Probe_Pairs!$B:$B,A6,Probe_Pairs!$S:$S,"Both halves") -> 0 | N6: dll | O6: Jeriel_HCRoligosequences.xlsx | Q6: stated in Jeriel's sheet | R6: LOC112055223 | S6: =IF(R6="","",COUNTIFS(Probe_Pairs!$B:$B,A6,Probe_Pairs!$X:$X,"Both halves")) -> 9 | T6: =IF(R6="","",IF(S6*2>=K6,"High","Low")) -> High | U6: homeotic protein distal-less isoform X1 | V6: homeotic protein distal-less | W6: XP_052743134.1; XP_052743133.1; XP_052743132.1
A7: JL-006 | B7: Jeriel | C7: drm | D7: protein drumstick | E7: Bicyclus anynana | F7: LOC112045021 | I7: B1 | J7: AF546 | K7: =COUNTIF(Probe_Pairs!$B:$B,A7) -> 6 | L7: =COUNTIFS(Probe_Pairs!$B:$B,A7,Probe_Pairs!$S:$S,"Both halves") -> 0 | M7: B2, B3 | N7: drumstick | O7: Jeriel_HCRoligosequences.xlsx | Q7: stated in Jeriel's sheet | R7: LOC112045021 | S7: =IF(R7="","",COUNTIFS(Probe_Pairs!$B:$B,A7,Probe_Pairs!$X:$X,"Both halves")) -> 3 | T7: =IF(R7="","",IF(S7*2>=K7,"High","Low")) -> High | U7: protein drumstick | V7: protein drumstick | W7: XP_023936823.1; XP_023936824.1; XP_023936825.1; XP_023936826.1 | AC7: Sheet note: 3 probes is fine
A8: JL-007 | B8: Jeriel | C8: exd | D8: homeobox protein extradenticle isoform X2 | E8: Bicyclus anynana | F8: LOC112056072 | I8: B1 | J8: AF546 | K8: =COUNTIF(Probe_Pairs!$B:$B,A8) -> 6 | L8: =COUNTIFS(Probe_Pairs!$B:$B,A8,Probe_Pairs!$S:$S,"Both halves") -> 0 | M8: B2 | N8: exd | O8: Jeriel_HCRoligosequences.xlsx | Q8: stated in Jeriel's sheet | R8: LOC112056072 | S8: =IF(R8="","",COUNTIFS(Probe_Pairs!$B:$B,A8,Probe_Pairs!$X:$X,"Both halves")) -> 6 | T8: =IF(R8="","",IF(S8*2>=K8,"High","Low")) -> High | U8: homeobox protein extradenticle isoform X2 | V8: homeobox protein extradenticle isoform X1 | W8: XP_052737190.1; XP_052737191.1
A9: JL-008 | B9: Jeriel | C9: fringe | D9: LOW QUALITY PROTEIN: fringe glycosyltransferase | E9: Bicyclus anynana | F9: LOC112056524 | I9: B1 | J9: AF546 | K9: =COUNTIF(Probe_Pairs!$B:$B,A9) -> 10 | L9: =COUNTIFS(Probe_Pairs!$B:$B,A9,Probe_Pairs!$S:$S,"Both halves") -> 0 | M9: B2, B3 | N9: fng | O9: Jeriel_HCRoligosequences.xlsx | Q9: stated in Jeriel's sheet | R9: LOC112056524 | S9: =IF(R9="","",COUNTIFS(Probe_Pairs!$B:$B,A9,Probe_Pairs!$X:$X,"Both halves")) -> 10 | T9: =IF(R9="","",IF(S9*2>=K9,"High","Low")) -> High | U9: LOW QUALITY PROTEIN: fringe glycosyltransferase | V9: fringe glycosyltransferase(LOC112056524) | W9: XP_023952733.2
A10: JL-009 | B10: Jeriel | C10: hth | D10: homeobox protein homothorax isoform X4 | E10: Bicyclus anynana | F10: LOC112054591 | I10: B1 | J10: AF546 | K10: =COUNTIF(Probe_Pairs!$B:$B,A10) -> 10 | L10: =COUNTIFS(Probe_Pairs!$B:$B,A10,Probe_Pairs!$S:$S,"Both halves") -> 0 | N10: hth | O10: Jeriel_HCRoligosequences.xlsx | Q10: stated in Jeriel's sheet | R10: LOC112054591 | S10: =IF(R10="","",COUNTIFS(Probe_Pairs!$B:$B,A10,Probe_Pairs!$X:$X,"Both halves")) -> 10 | T10: =IF(R10="","",IF(S10*2>=K10,"High","Low")) -> High | U10: homeobox protein homothorax isoform X4 | V10: homeobox protein homothorax isoform X1 | W10: XP_052744213.1; XP_052744214.1; XP_023950201.1; XP_052744215.1
A11: JL-010 | B11: Jeriel | C11: nubbin | D11: POU domain, class 2, transcription factor 3L-like | E11: Bicyclus anynana | F11: LOC112053646 | I11: B1 | J11: AF546 | K11: =COUNTIF(Probe_Pairs!$B:$B,A11) -> 10 | L11: =COUNTIFS(Probe_Pairs!$B:$B,A11,Probe_Pairs!$S:$S,"Both halves") -> 0 | N11: nubbin-like | O11: Jeriel_HCRoligosequences.xlsx | Q11: stated in Jeriel's sheet | R11: LOC112053646 | S11: =IF(R11="","",COUNTIFS(Probe_Pairs!$B:$B,A11,Probe_Pairs!$X:$X,"Both halves")) -> 10 | T11: =IF(R11="","",IF(S11*2>=K11,"High","Low")) -> High | U11: POU domain, class 2, transcription factor 3L-like | V11: protein nubbin-like | W11: XP_052741896.1
A12: JL-011 | B12: Jeriel | C12: pannier | D12: homeobox protein araucan isoform X2 | E12: Bicyclus anynana | F12: LOC112048938 | I12: B1 | J12: AF546 | K12: =COUNTIF(Probe_Pairs!$B:$B,A12) -> 9 | L12: =COUNTIFS(Probe_Pairs!$B:$B,A12,Probe_Pairs!$S:$S,"Both halves") -> 0 | N12: pnr | O12: Jeriel_HCRoligosequences.xlsx | Q12: stated in Jeriel's sheet | R12: LOC112045732 | S12: =IF(R12="","",COUNTIFS(Probe_Pairs!$B:$B,A12,Probe_Pairs!$X:$X,"Both halves")) -> 9 | T12: =IF(R12="","",IF(S12*2>=K12,"High","Low")) -> High | U12: homeobox protein araucan isoform X2 | V12: homeobox protein araucan-like isoform X1 | W12: XP_023937802.1; XP_023937803.1 | X12: Recorded LOC differs from the genome match; the probes match the LOC recorded for araucan (possible swap); 3 pair(s) flagged in Probe_Pairs
A13: JL-012 | B13: Jeriel | C13: rotund | D13: zinc finger protein rotund-like isoform X4 | E13: Bicyclus anynana | F13: LOC112056645 | I13: B1 | J13: AF546 | K13: =COUNTIF(Probe_Pairs!$B:$B,A13) -> 3 | L13: =COUNTIFS(Probe_Pairs!$B:$B,A13,Probe_Pairs!$S:$S,"Both halves") -> 0 | M13: B3 | N13: rotund | O13: Jeriel_HCRoligosequences.xlsx | Q13: stated in Jeriel's sheet | R13: LOC112056645 | S13: =IF(R13="","",COUNTIFS(Probe_Pairs!$B:$B,A13,Probe_Pairs!$X:$X,"Both halves")) -> 3 | T13: =IF(R13="","",IF(S13*2>=K13,"High","Low")) -> High | U13: zinc finger protein rotund-like isoform X4 | V13: uncharacterized LOC112056645(LOC112056645) | W13: XP_052745353.1; XP_052745354.1; XP_052745352.1; XP_023952346.2
A14: JL-013 | B14: Jeriel | C14: scr | D14: homeotic protein Sex combs reduced | E14: Bicyclus anynana | F14: LOC112057777 | I14: B1 | J14: AF546 | K14: =COUNTIF(Probe_Pairs!$B:$B,A14) -> 12 | L14: =COUNTIFS(Probe_Pairs!$B:$B,A14,Probe_Pairs!$S:$S,"Both halves") -> 0 | N14: scr | O14: Jeriel_HCRoligosequences.xlsx | Q14: stated in Jeriel's sheet | R14: LOC112057777 | S14: =IF(R14="","",COUNTIFS(Probe_Pairs!$B:$B,A14,Probe_Pairs!$X:$X,"Both halves")) -> 12 | T14: =IF(R14="","",IF(S14*2>=K14,"High","Low")) -> High | U14: homeotic protein Sex combs reduced | V14: homeotic protein Sex combs reduced | W14: XP_023954086.1
A15: JL-014 | B15: Jeriel | C15: sob | D15: protein sister of odd and bowel-like | E15: Bicyclus anynana | F15: LOC112044996 | I15: B1 | J15: AF546 | K15: =COUNTIF(Probe_Pairs!$B:$B,A15) -> 8 | L15: =COUNTIFS(Probe_Pairs!$B:$B,A15,Probe_Pairs!$S:$S,"Both halves") -> 0 | N15: sob | O15: Jeriel_HCRoligosequences.xlsx | Q15: stated in Jeriel's sheet | R15: LOC112044996 | S15: =IF(R15="","",COUNTIFS(Probe_Pairs!$B:$B,A15,Probe_Pairs!$X:$X,"Both halves")) -> 8 | T15: =IF(R15="","",IF(S15*2>=K15,"High","Low")) -> High | U15: protein sister of odd and bowel-like | V15: protein sister of odd and bowel-like | W15: XP_023936789.1
A16: JL-015 | B16: Jeriel | C16: tiptop | D16: protein tiptop-like isoform X2 | E16: Bicyclus anynana | F16: LOC112051061 | I16: B1 | J16: AF546 | K16: =COUNTIF(Probe_Pairs!$B:$B,A16) -> 12 | L16: =COUNTIFS(Probe_Pairs!$B:$B,A16,Probe_Pairs!$S:$S,"Both halves") -> 0 | N16: tio | O16: Jeriel_HCRoligosequences.xlsx | Q16: stated in Jeriel's sheet | R16: LOC112051061 | S16: =IF(R16="","",COUNTIFS(Probe_Pairs!$B:$B,A16,Probe_Pairs!$X:$X,"Both halves")) -> 12 | T16: =IF(R16="","",IF(S16*2>=K16,"High","Low")) -> High | U16: protein tiptop-like isoform X2 | V16: protein tiptop-like isoform X1 | W16: XP_023945294.1; XP_023945304.1; XP_023945313.1
A17: JL-016 | B17: Jeriel | C17: vestigial | D17: protein vestigial | E17: Bicyclus anynana | F17: LOC112043588 | I17: B1 | J17: AF546 | K17: =COUNTIF(Probe_Pairs!$B:$B,A17) -> 12 | L17: =COUNTIFS(Probe_Pairs!$B:$B,A17,Probe_Pairs!$S:$S,"Both halves") -> 0 | M17: B2, B3 | N17: vg | O17: Jeriel_HCRoligosequences.xlsx | Q17: stated in Jeriel's sheet | R17: LOC112043588 | S17: =IF(R17="","",COUNTIFS(Probe_Pairs!$B:$B,A17,Probe_Pairs!$X:$X,"Both halves")) -> 12 | T17: =IF(R17="","",IF(S17*2>=K17,"High","Low")) -> High | U17: protein vestigial | V17: protein vestigial | W17: XP_023934840.1
A18: JL-017 | B18: Jeriel | C18: Wnt-1 | D18: protein Wnt-1 | E18: Bicyclus anynana | F18: LOC112058530 | I18: B1 | J18: AF546 | K18: =COUNTIF(Probe_Pairs!$B:$B,A18) -> 12 | L18: =COUNTIFS(Probe_Pairs!$B:$B,A18,Probe_Pairs!$S:$S,"Both halves") -> 0 | M18: B3 | N18: B1_P1 (wnt1 1.1)_1, B1_P1 (wnt1 1.1)_2, B1_P1 (wnt1 1.1)_3, B1_P1 (wnt1 1.1)_4, B1_P1 (wnt1 1.1)_5, B1_P1 (wnt1 1.1)_6, B1_P1 (wnt1 1.1)_7, B1_P1 (wnt1 1.1)_8 | O18: Jeriel_HCRoligosequences.xlsx | Q18: stated in Jeriel's sheet | R18: LOC112058530 | S18: =IF(R18="","",COUNTIFS(Probe_Pairs!$B:$B,A18,Probe_Pairs!$X:$X,"Both halves")) -> 12 | T18: =IF(R18="","",IF(S18*2>=K18,"High","Low")) -> High | U18: protein Wnt-1 | V18: protein Wnt-1 | W18: XP_023955185.1
A19: JL-018 | B19: Jeriel | C19: 18w (toll-like receptor 7) | D19: toll-like receptor 7 | E19: Bicyclus anynana | F19: LOC112047337 | I19: B2 | J19: AF647 | K19: =COUNTIF(Probe_Pairs!$B:$B,A19) -> 8 | L19: =COUNTIFS(Probe_Pairs!$B:$B,A19,Probe_Pairs!$S:$S,"Both halves") -> 0 | M19: B3 | N19: 18w | O19: Jeriel_HCRoligosequences.xlsx | Q19: genome_cds.fa match | R19: LOC112047337 | S19: =IF(R19="","",COUNTIFS(Probe_Pairs!$B:$B,A19,Probe_Pairs!$X:$X,"Both halves")) -> 8 | T19: =IF(R19="","",IF(S19*2>=K19,"High","Low")) -> High | U19: toll-like receptor 7 | V19: toll-like receptor 7 | W19: XP_023940195.2
A20: JL-019 | B20: Jeriel | C20: 22-like | D20: dual specificity protein phosphatase 22-like | E20: Bicyclus anynana | F20: LOC112051899 | I20: B2 | J20: AF647 | K20: =COUNTIF(Probe_Pairs!$B:$B,A20) -> 8 | L20: =COUNTIFS(Probe_Pairs!$B:$B,A20,Probe_Pairs!$S:$S,"Both halves") -> 0 | M20: B3 | N20: 22like | O20: Jeriel_HCRoligosequences.xlsx | Q20: stated in Jeriel's sheet | R20: LOC112051899 | S20: =IF(R20="","",COUNTIFS(Probe_Pairs!$B:$B,A20,Probe_Pairs!$X:$X,"Both halves")) -> 8 | T20: =IF(R20="","",IF(S20*2>=K20,"High","Low")) -> High | U20: dual specificity protein phosphatase 22-like | V20: dual specificity protein phosphatase 22-like isoform X2 | W20: XP_052741740.1 | Y20: Designed | AC20: Sheet note: blastp droso puckered
A21: JL-020 | B21: Jeriel | C21: apterous A | D21: protein apterous | E21: Bicyclus anynana | F21: LOC112045866 | I21: B2 | J21: AF647 | K21: =COUNTIF(Probe_Pairs!$B:$B,A21) -> 8 | L21: =COUNTIFS(Probe_Pairs!$B:$B,A21,Probe_Pairs!$S:$S,"Both halves") -> 0 | N21: ap | O21: Jeriel_HCRoligosequences.xlsx | Q21: stated in Jeriel's sheet | R21: LOC112045866 | S21: =IF(R21="","",COUNTIFS(Probe_Pairs!$B:$B,A21,Probe_Pairs!$X:$X,"Both halves")) -> 8 | T21: =IF(R21="","",IF(S21*2>=K21,"High","Low")) -> High | U21: protein apterous | V21: protein apterous-like isoform X1 | W21: XP_023937999.1
A22: JL-021 | B22: Jeriel | C22: araucan | D22: GATA-binding factor A isoform X3 | E22: Bicyclus anynana | F22: LOC112045732 | I22: B2 | J22: AF647 | K22: =COUNTIF(Probe_Pairs!$B:$B,A22) -> 9 | L22: =COUNTIFS(Probe_Pairs!$B:$B,A22,Probe_Pairs!$S:$S,"Both halves") -> 0 | N22: ara | O22: Jeriel_HCRoligosequences.xlsx | Q22: stated in Jeriel's sheet | R22: LOC112048938 | S22: =IF(R22="","",COUNTIFS(Probe_Pairs!$B:$B,A22,Probe_Pairs!$X:$X,"Both halves")) -> 9 | T22: =IF(R22="","",IF(S22*2>=K22,"High","Low")) -> High | U22: GATA-binding factor A isoform X3 | V22: GATA-binding factor A-like | W22: XP_052747468.1; XP_052747469.1; XP_052747470.1 | X22: Recorded LOC differs from the genome match; the probes match the LOC recorded for pannier (possible swap)
A23: JL-022 | B23: Jeriel | C23: bric-a-bac | D23: protein bric-a-brac 1 isoform X1 | E23: Bicyclus anynana | F23: LOC112043806 | I23: B2 | J23: AF647 | K23: =COUNTIF(Probe_Pairs!$B:$B,A23) -> 8 | L23: =COUNTIFS(Probe_Pairs!$B:$B,A23,Probe_Pairs!$S:$S,"Both halves") -> 0 | N23: bab | O23: Jeriel_HCRoligosequences.xlsx | Q23: stated in Jeriel's sheet | R23: LOC112043806 | S23: =IF(R23="","",COUNTIFS(Probe_Pairs!$B:$B,A23,Probe_Pairs!$X:$X,"Both halves")) -> 8 | T23: =IF(R23="","",IF(S23*2>=K23,"High","Low")) -> High | U23: protein bric-a-brac 1 isoform X1 | V23: protein bric-a-brac 1-like | W23: XP_052746695.1; XP_023935169.2; XP_052746694.1
A24: JL-023 | B24: Jeriel | C24: cut | D24: homeobox protein cut isoform X4 | E24: Bicyclus anynana | F24: LOC112051626 | I24: B2 | J24: AF647 | K24: =COUNTIF(Probe_Pairs!$B:$B,A24) -> 10 | L24: =COUNTIFS(Probe_Pairs!$B:$B,A24,Probe_Pairs!$S:$S,"Both halves") -> 0 | N24: cut | O24: Jeriel_HCRoligosequences.xlsx | Q24: stated in Jeriel's sheet | R24: LOC112051626 | S24: =IF(R24="","",COUNTIFS(Probe_Pairs!$B:$B,A24,Probe_Pairs!$X:$X,"Both halves")) -> 10 | T24: =IF(R24="","",IF(S24*2>=K24,"High","Low")) -> High | U24: homeobox protein cut isoform X4 | V24: homeobox protein cut isoform X1 | W24: XP_023946111.1; XP_023946113.1; XP_023946110.1; XP_023946109.1; XP_052738760.1; XP_023946112.1
A25: JL-024 | B25: Jeriel | C25: dishevelled | D25: segment polarity protein dishevelled homolog DVL-3 | E25: Bicyclus anynana | F25: LOC112056023 | I25: B2 | J25: AF647 | K25: =COUNTIF(Probe_Pairs!$B:$B,A25) -> 12 | L25: =COUNTIFS(Probe_Pairs!$B:$B,A25,Probe_Pairs!$S:$S,"Both halves") -> 0 | N25: dsh | O25: Jeriel_HCRoligosequences.xlsx | Q25: stated in Jeriel's sheet | R25: LOC112056023 | S25: =IF(R25="","",COUNTIFS(Probe_Pairs!$B:$B,A25,Probe_Pairs!$X:$X,"Both halves")) -> 12 | T25: =IF(R25="","",IF(S25*2>=K25,"High","Low")) -> High | U25: segment polarity protein dishevelled homolog DVL-3 | V25: segment polarity protein dishevelled homolog DVL-3-like | W25: XP_023952113.2
A26: JL-025 | B26: Jeriel | C26: dpp | D26: protein decapentaplegic | E26: Bicyclus anynana | F26: LOC112044871 | I26: B2 | J26: AF647 | K26: =COUNTIF(Probe_Pairs!$B:$B,A26) -> 8 | L26: =COUNTIFS(Probe_Pairs!$B:$B,A26,Probe_Pairs!$S:$S,"Both halves") -> 0 | N26: dpp | O26: Jeriel_HCRoligosequences.xlsx | Q26: stated in Jeriel's sheet | R26: LOC112044871 | S26: =IF(R26="","",COUNTIFS(Probe_Pairs!$B:$B,A26,Probe_Pairs!$X:$X,"Both halves")) -> 8 | T26: =IF(R26="","",IF(S26*2>=K26,"High","Low")) -> High | U26: protein decapentaplegic | V26: protein decapentaplegic | W26: XP_023936626.1; XP_052739615.1
A27: JL-026 | B27: Jeriel | C27: drm | D27: protein drumstick | E27: Bicyclus anynana | F27: LOC112045021 | I27: B2 | J27: AF647 | K27: =COUNTIF(Probe_Pairs!$B:$B,A27) -> 3 | L27: =COUNTIFS(Probe_Pairs!$B:$B,A27,Probe_Pairs!$S:$S,"Both halves") -> 0 | M27: B1, B3 | N27: drm | O27: Jeriel_HCRoligosequences.xlsx | Q27: stated in Jeriel's sheet | R27: LOC112045021 | S27: =IF(R27="","",COUNTIFS(Probe_Pairs!$B:$B,A27,Probe_Pairs!$X:$X,"Both halves")) -> 3 | T27: =IF(R27="","",IF(S27*2>=K27,"High","Low")) -> High | U27: protein drumstick | V27: protein drumstick | W27: XP_023936823.1; XP_023936824.1; XP_023936825.1; XP_023936826.1 | AC27: Sheet note: 3 probes is fine
A28: JL-027 | B28: Jeriel | C28: exd | D28: homeobox protein extradenticle isoform X2 | E28: Bicyclus anynana | F28: LOC112056072 | I28: B2 | J28: AF647 | K28: =COUNTIF(Probe_Pairs!$B:$B,A28) -> 8 | L28: =COUNTIFS(Probe_Pairs!$B:$B,A28,Probe_Pairs!$S:$S,"Both halves") -> 0 | M28: B1 | N28: exd, Exd | O28: Jeriel_HCRoligosequences.xlsx | Q28: stated in Jeriel's sheet | R28: LOC112056072 | S28: =IF(R28="","",COUNTIFS(Probe_Pairs!$B:$B,A28,Probe_Pairs!$X:$X,"Both halves")) -> 8 | T28: =IF(R28="","",IF(S28*2>=K28,"High","Low")) -> High | U28: homeobox protein extradenticle isoform X2 | V28: homeobox protein extradenticle isoform X1 | W28: XP_052737190.1; XP_052737191.1
A29: JL-028 | B29: Jeriel | C29: fringe | D29: LOW QUALITY PROTEIN: fringe glycosyltransferase | E29: Bicyclus anynana | F29: LOC112056524 | I29: B2 | J29: AF647 | K29: =COUNTIF(Probe_Pairs!$B:$B,A29) -> 10 | L29: =COUNTIFS(Probe_Pairs!$B:$B,A29,Probe_Pairs!$S:$S,"Both halves") -> 0 | M29: B1, B3 | N29: fng | O29: Jeriel_HCRoligosequences.xlsx | Q29: stated in Jeriel's sheet | R29: LOC112056524 | S29: =IF(R29="","",COUNTIFS(Probe_Pairs!$B:$B,A29,Probe_Pairs!$X:$X,"Both halves")) -> 10 | T29: =IF(R29="","",IF(S29*2>=K29,"High","Low")) -> High | U29: LOW QUALITY PROTEIN: fringe glycosyltransferase | V29: fringe glycosyltransferase(LOC112056524) | W29: XP_023952733.2
A30: JL-029 | B30: Jeriel | C30: Lhx1 | D30: LIM/homeobox protein Lhx1 isoform X3 | E30: Bicyclus anynana | F30: LOC112054918 | I30: B2 | J30: AF647 | K30: =COUNTIF(Probe_Pairs!$B:$B,A30) -> 8 | L30: =COUNTIFS(Probe_Pairs!$B:$B,A30,Probe_Pairs!$S:$S,"Both halves") -> 0 | N30: lhx1 | O30: Jeriel_HCRoligosequences.xlsx | Q30: stated in Jeriel's sheet | R30: LOC112054918 | S30: =IF(R30="","",COUNTIFS(Probe_Pairs!$B:$B,A30,Probe_Pairs!$X:$X,"Both halves")) -> 8 | T30: =IF(R30="","",IF(S30*2>=K30,"High","Low")) -> High | U30: LIM/homeobox protein Lhx1 isoform X3 | V30: LIM/homeobox protein Lhx1-like | W30: XP_052739080.1; XP_052739079.1; XP_052739081.1
A31: JL-030 | B31: Jeriel | C31: mpk3 | D31: dual specificity protein phosphatase Mpk3 | E31: Bicyclus anynana | F31: LOC112048567 | I31: B2 | J31: AF647 | K31: =COUNTIF(Probe_Pairs!$B:$B,A31) -> 8 | L31: =COUNTIFS(Probe_Pairs!$B:$B,A31,Probe_Pairs!$S:$S,"Both halves") -> 0 | N31: mpk3 | O31: Jeriel_HCRoligosequences.xlsx | Q31: stated in Jeriel's sheet | R31: LOC112048567 | S31: =IF(R31="","",COUNTIFS(Probe_Pairs!$B:$B,A31,Probe_Pairs!$X:$X,"Both halves")) -> 8 | T31: =IF(R31="","",IF(S31*2>=K31,"High","Low")) -> High | U31: dual specificity protein phosphatase Mpk3 | V31: dual specificity protein phosphatase Mpk3 | W31: XP_023941915.2 | Y31: Designed | AC31: Sheet note: blastx droso puckered
A32: JL-031 | B32: Jeriel | C32: rac | D32: rac GTPase-activating protein 1 | E32: Bicyclus anynana | F32: LOC112045044 | I32: B2 | J32: AF647 | K32: =COUNTIF(Probe_Pairs!$B:$B,A32) -> 8 | L32: =COUNTIFS(Probe_Pairs!$B:$B,A32,Probe_Pairs!$S:$S,"Both halves") -> 0 | N32: rac | O32: Jeriel_HCRoligosequences.xlsx | Q32: stated in Jeriel's sheet | R32: LOC112045044 | S32: =IF(R32="","",COUNTIFS(Probe_Pairs!$B:$B,A32,Probe_Pairs!$X:$X,"Both halves")) -> 8 | T32: =IF(R32="","",IF(S32*2>=K32,"High","Low")) -> High | U32: rac GTPase-activating protein 1 | V32: rac GTPase-activating protein 1-like | W32: XP_052741230.1
A33: JL-032 | B33: Jeriel | C33: rho-GTPase activating protein p | D33: rho GTPase-activating protein 190 isoform X3 | E33: Bicyclus anynana | F33: LOC112056068 | I33: B2 | J33: AF647 | K33: =COUNTIF(Probe_Pairs!$B:$B,A33) -> 8 | L33: =COUNTIFS(Probe_Pairs!$B:$B,A33,Probe_Pairs!$S:$S,"Both halves") -> 0 | N33: rgap190 | O33: Jeriel_HCRoligosequences.xlsx | Q33: stated in Jeriel's sheet | R33: LOC112056068 | S33: =IF(R33="","",COUNTIFS(Probe_Pairs!$B:$B,A33,Probe_Pairs!$X:$X,"Both halves")) -> 8 | T33: =IF(R33="","",IF(S33*2>=K33,"High","Low")) -> High | U33: rho GTPase-activating protein 190 isoform X3 | V33: rho GTPase-activating protein 190 | W33: XP_052745228.1; XP_052745229.1; XP_052745230.1; XP_052745231.1; XP_052745232.1 | AC33: Sheet note: transcript variant X1
A34: JL-033 | B34: Jeriel | C34: scalloped | D34: protein scalloped isoform X1 | E34: Bicyclus anynana | F34: LOC112049271 | I34: B2 | J34: AF647 | K34: =COUNTIF(Probe_Pairs!$B:$B,A34) -> 6 | L34: =COUNTIFS(Probe_Pairs!$B:$B,A34,Probe_Pairs!$S:$S,"Both halves") -> 0 | N34: scalloped | O34: Jeriel_HCRoligosequences.xlsx | Q34: genome_cds.fa match | R34: LOC112049271 | S34: =IF(R34="","",COUNTIFS(Probe_Pairs!$B:$B,A34,Probe_Pairs!$X:$X,"Both halves")) -> 6 | T34: =IF(R34="","",IF(S34*2>=K34,"High","Low")) -> High | U34: protein scalloped isoform X1 | V34: protein scalloped isoform X3 | W34: XP_052738202.1; XP_023942867.1 | X34: Sheet note says these probes came from Tirtha | AC34: Sheet note: (^ from tirtha)
A35: JL-034 | B35: Jeriel | C35: ss | D35: aryl hydrocarbon receptor isoform X2 | E35: Bicyclus anynana | F35: LOC112043391 | I35: B2 | J35: AF647 | K35: =COUNTIF(Probe_Pairs!$B:$B,A35) -> 10 | L35: =COUNTIFS(Probe_Pairs!$B:$B,A35,Probe_Pairs!$S:$S,"Both halves") -> 0 | N35: ss | O35: Jeriel_HCRoligosequences.xlsx | Q35: genome_cds.fa match | R35: LOC112043391 | S35: =IF(R35="","",COUNTIFS(Probe_Pairs!$B:$B,A35,Probe_Pairs!$X:$X,"Both halves")) -> 10 | T35: =IF(R35="","",IF(S35*2>=K35,"High","Low")) -> High | U35: aryl hydrocarbon receptor isoform X2 | V35: aryl hydrocarbon receptor | W35: XP_052744340.1; XP_023934560.1
A36: JL-035 | B36: Jeriel | C36: ubx | D36: homeotic protein ultrabithorax | E36: Bicyclus anynana | F36: LOC112057782 | I36: B2 | J36: AF647 | K36: =COUNTIF(Probe_Pairs!$B:$B,A36) -> 9 | L36: =COUNTIFS(Probe_Pairs!$B:$B,A36,Probe_Pairs!$S:$S,"Both halves") -> 0 | N36: ubx | O36: Jeriel_HCRoligosequences.xlsx | Q36: genome_cds.fa match | R36: LOC112057782 | S36: =IF(R36="","",COUNTIFS(Probe_Pairs!$B:$B,A36,Probe_Pairs!$X:$X,"Both halves")) -> 9 | T36: =IF(R36="","",IF(S36*2>=K36,"High","Low")) -> High | U36: homeotic protein ultrabithorax | V36: homeotic protein ultrabithorax | W36: XP_052739699.1
A37: JL-036 | B37: Jeriel | C37: uncharacterised (droso raw) | D37: uncharacterized protein LOC112043347 isoform X4 | E37: Bicyclus anynana | F37: LOC112043347 | I37: B2 | J37: AF647 | K37: =COUNTIF(Probe_Pairs!$B:$B,A37) -> 8 | L37: =COUNTIFS(Probe_Pairs!$B:$B,A37,Probe_Pairs!$S:$S,"Both halves") -> 0 | M37: B3 | N37: raw | O37: Jeriel_HCRoligosequences.xlsx | Q37: stated in Jeriel's sheet | R37: LOC112043347 | S37: =IF(R37="","",COUNTIFS(Probe_Pairs!$B:$B,A37,Probe_Pairs!$X:$X,"Both halves")) -> 8 | T37: =IF(R37="","",IF(S37*2>=K37,"High","Low")) -> High | U37: uncharacterized protein LOC112043347 isoform X4 | V37: uncharacterized LOC112043347(LOC112043347) | W37: XP_023934495.2; XP_023934490.2; XP_023934493.2; XP_052737221.1 | Y37: Designed | AC37: Sheet note: blastx droso raw
A38: JL-037 | B38: Jeriel | C38: vestigial | D38: protein vestigial | E38: Bicyclus anynana | F38: LOC112043588 | I38: B2 | J38: AF647 | K38: =COUNTIF(Probe_Pairs!$B:$B,A38) -> 6 | L38: =COUNTIFS(Probe_Pairs!$B:$B,A38,Probe_Pairs!$S:$S,"Both halves") -> 0 | M38: B1, B3 | N38: vg | O38: Jeriel_HCRoligosequences.xlsx | Q38: stated in Jeriel's sheet | R38: LOC112043588 | S38: =IF(R38="","",COUNTIFS(Probe_Pairs!$B:$B,A38,Probe_Pairs!$X:$X,"Both halves")) -> 6 | T38: =IF(R38="","",IF(S38*2>=K38,"High","Low")) -> High | U38: protein vestigial | V38: protein vestigial | W38: XP_023934840.1
A39: JL-038 | B39: Jeriel | C39: 18w (toll-like receptor 7) | D39: toll-like receptor 7 | E39: Bicyclus anynana | F39: LOC112047337 | I39: B3 | J39: AF488 | K39: =COUNTIF(Probe_Pairs!$B:$B,A39) -> 8 | L39: =COUNTIFS(Probe_Pairs!$B:$B,A39,Probe_Pairs!$S:$S,"Both halves") -> 0 | M39: B2 | N39: 18w | O39: Jeriel_HCRoligosequences.xlsx | Q39: genome_cds.fa match | R39: LOC112047337 | S39: =IF(R39="","",COUNTIFS(Probe_Pairs!$B:$B,A39,Probe_Pairs!$X:$X,"Both halves")) -> 8 | T39: =IF(R39="","",IF(S39*2>=K39,"High","Low")) -> High | U39: toll-like receptor 7 | V39: toll-like receptor 7 | W39: XP_023940195.2
A40: JL-039 | B40: Jeriel | C40: 22-like | D40: dual specificity protein phosphatase 22-like | E40: Bicyclus anynana | F40: LOC112051899 | I40: B3 | J40: AF488 | K40: =COUNTIF(Probe_Pairs!$B:$B,A40) -> 8 | L40: =COUNTIFS(Probe_Pairs!$B:$B,A40,Probe_Pairs!$S:$S,"Both halves") -> 0 | M40: B2 | N40: 22-like | O40: Jeriel_HCRoligosequences.xlsx | Q40: stated in Jeriel's sheet | R40: LOC112051899 | S40: =IF(R40="","",COUNTIFS(Probe_Pairs!$B:$B,A40,Probe_Pairs!$X:$X,"Both halves")) -> 8 | T40: =IF(R40="","",IF(S40*2>=K40,"High","Low")) -> High | U40: dual specificity protein phosphatase 22-like | V40: dual specificity protein phosphatase 22-like isoform X2 | W40: XP_052741740.1 | Y40: Designed | AC40: Sheet note: blastp droso puckered
...

Sheet Probe_Pairs
A1: Pair_ID | B1: Set_ID | C1: Gene | D1: Amplifier | E1: Pair # | F1: P1 standard name | G1: P1 sequence (5′→3′) | H1: P2 standard name | I1: P2 sequence (5′→3′) | J1: P1 original name(s) | K1: P2 original name(s) | L1: P1 binding arm | M1: P2 binding arm | N1: P1 arm length | O1: P2 arm length | P1: P1 arm GC% | Q1: P2 arm GC% | R1: Template | S1: Template match | T1: Site start on template (nt) | U1: Paired by | V1: Source files | W1: Pool / order (as recorded) | X1: Genome match (to set LOC) | Y1: Pair flag
A2: JL-001-01 | B2: JL-001 | C2: B-H1 | D2: B1 | E2: 1 | F2: B-H1_B1_P1_01 | G2: GAGGAGGGCAGCAAACGGAACTTGATACATCGTCTGAGTCGTCTT | H2: B-H1_B1_P2_01 | I2: GCTGAGGCGTCGCCGCCACACGACTTAGAAGAGTCTTCCTTTACG | J2: B1_P1 (B-H1)_1; B-H11_HCR_P1B1 | K2: B1_P2 (B-H1)_1; B-H11_HCR_P1B2 | L2: CTTGATACATCGTCTGAGTCGTCTT | M2: GCTGAGGCGTCGCCGCCACACGACT | N2: =LEN(L2) -> 25 | O2: =LEN(M2) -> 25 | P2: =IF(N2=0,"",(N2-LEN(SUBSTITUTE(SUBSTITUTE(L2,"G",""),"C","")))/N2) -> 0.44 | Q2: =IF(O2=0,"",(O2-LEN(SUBSTITUTE(SUBSTITUTE(M2,"G",""),"C","")))/O2) -> 0.72 | S2: No template | U2: genome position | V2: Jeriel_HCRoligosequences › B-H1 | X2: Both halves | Y2: P2 named as B-H11_HCR_P1B2
A3: JL-001-02 | B3: JL-001 | C3: B-H1 | D3: B1 | E3: 2 | F3: B-H1_B1_P1_02 | G3: GAGGAGGGCAGCAAACGGAAGTCCGTGAAGGCTGTCCTCGCTTTC | H3: B-H1_B1_P2_02 | I3: CGACTTCTCCAGGGTCTGGAGCTGGTAGAAGAGTCTTCCTTTACG | J3: B1_P1 (B-H1)_2; B-H12_HCR_P1B1 | K3: B1_P2 (B-H1)_2; B-H12_HCR_P1B2 | L3: GTCCGTGAAGGCTGTCCTCGCTTTC | M3: CGACTTCTCCAGGGTCTGGAGCTGG | N3: =LEN(L3) -> 25 | O3: =LEN(M3) -> 25 | P3: =IF(N3=0,"",(N3-LEN(SUBSTITUTE(SUBSTITUTE(L3,"G",""),"C","")))/N3) -> 0.6 | Q3: =IF(O3=0,"",(O3-LEN(SUBSTITUTE(SUBSTITUTE(M3,"G",""),"C","")))/O3) -> 0.64 | S3: No template | U3: genome position | V3: Jeriel_HCRoligosequences › B-H1 | X3: Both halves | Y3: P2 named as B-H12_HCR_P1B2
A4: JL-001-03 | B4: JL-001 | C4: B-H1 | D4: B1 | E4: 3 | F4: B-H1_B1_P1_03 | G4: GAGGAGGGCAGCAAACGGAAGCTCCATGCGGTCCTGTACACTGAG | H4: B-H1_B1_P2_03 | I4: TGTCCGTAAGGCCCAGTTTGGCGGCTAGAAGAGTCTTCCTTTACG | J4: B1_P1 (B-H1)_3; B-H13_HCR_P1B1 | K4: B1_P2 (B-H1)_3; B-H13_HCR_P1B2 | L4: GCTCCATGCGGTCCTGTACACTGAG | M4: TGTCCGTAAGGCCCAGTTTGGCGGC | N4: =LEN(L4) -> 25 | O4: =LEN(M4) -> 25 | P4: =IF(N4=0,"",(N4-LEN(SUBSTITUTE(SUBSTITUTE(L4,"G",""),"C","")))/N4) -> 0.6 | Q4: =IF(O4=0,"",(O4-LEN(SUBSTITUTE(SUBSTITUTE(M4,"G",""),"C","")))/O4) -> 0.64 | S4: No template | U4: genome position | V4: Jeriel_HCRoligosequences › B-H1 | X4: Both halves | Y4: P2 named as B-H13_HCR_P1B2
A5: JL-001-04 | B5: JL-001 | C5: B-H1 | D5: B1 | E5: 4 | F5: B-H1_B1_P1_04 | G5: GAGGAGGGCAGCAAACGGAATTCCATTTCGTCCGTCTATTTTGGT | H5: B-H1_B1_P2_04 | I5: AGCTCCAGCCCGACGGCGGTTTGACTAGAAGAGTCTTCCTTTACG | J5: B1_P1 (B-H1)_4; B-H14_HCR_P1B1 | K5: B1_P2 (B-H1)_4; B-H14_HCR_P1B2 | L5: TTCCATTTCGTCCGTCTATTTTGGT | M5: AGCTCCAGCCCGACGGCGGTTTGAC | N5: =LEN(L5) -> 25 | O5: =LEN(M5) -> 25 | P5: =IF(N5=0,"",(N5-LEN(SUBSTITUTE(SUBSTITUTE(L5,"G",""),"C","")))/N5) -> 0.4 | Q5: =IF(O5=0,"",(O5-LEN(SUBSTITUTE(SUBSTITUTE(M5,"G",""),"C","")))/O5) -> 0.68 | S5: No template | U5: genome position | V5: Jeriel_HCRoligosequences › B-H1 | X5: Both halves | Y5: P2 named as B-H14_HCR_P1B2
A6: JL-001-05 | B6: JL-001 | C6: B-H1 | D6: B1 | E6: 5 | F6: B-H1_B1_P1_05 | G6: GAGGAGGGCAGCAAACGGAAGTACAGCCGCTGCAGCGCTGCGTAG | H6: B-H1_B1_P2_05 | I6: GGCCGGCACCCCGGCCCAGTAGCCGTAGAAGAGTCTTCCTTTACG | J6: B1_P1 (B-H1)_5; B-H15_HCR_P1B1 | K6: B1_P2 (B-H1)_5; B-H15_HCR_P1B2 | L6: GTACAGCCGCTGCAGCGCTGCGTAG | M6: GGCCGGCACCCCGGCCCAGTAGCCG | N6: =LEN(L6) -> 25 | O6: =LEN(M6) -> 25 | P6: =IF(N6=0,"",(N6-LEN(SUBSTITUTE(SUBSTITUTE(L6,"G",""),"C","")))/N6) -> 0.68 | Q6: =IF(O6=0,"",(O6-LEN(SUBSTITUTE(SUBSTITUTE(M6,"G",""),"C","")))/O6) -> 0.84 | S6: No template | U6: genome position | V6: Jeriel_HCRoligosequences › B-H1 | X6: Both halves | Y6: P2 named as B-H15_HCR_P1B2
A7: JL-001-06 | B7: JL-001 | C7: B-H1 | D7: B1 | E7: 6 | F7: B-H1_B1_P1_06 | G7: GAGGAGGGCAGCAAACGGAAGCCGGTAGTAGAGGTCGGCGGCGGG | H7: B-H1_B1_P2_06 | I7: CGGCGGCAGCGGCGTTGGCGGCGGCTAGAAGAGTCTTCCTTTACG | J7: B1_P1 (B-H1)_6; B-H16_HCR_P1B1 | K7: B1_P2 (B-H1)_6; B-H16_HCR_P1B2 | L7: GCCGGTAGTAGAGGTCGGCGGCGGG | M7: CGGCGGCAGCGGCGTTGGCGGCGGC | N7: =LEN(L7) -> 25 | O7: =LEN(M7) -> 25 | P7: =IF(N7=0,"",(N7-LEN(SUBSTITUTE(SUBSTITUTE(L7,"G",""),"C","")))/N7) -> 0.76 | Q7: =IF(O7=0,"",(O7-LEN(SUBSTITUTE(SUBSTITUTE(M7,"G",""),"C","")))/O7) -> 0.88 | S7: No template | U7: genome position | V7: Jeriel_HCRoligosequences › B-H1 | X7: Both halves | Y7: P2 named as B-H16_HCR_P1B2
A8: JL-001-07 | B8: JL-001 | C8: B-H1 | D8: B1 | E8: 7 | F8: B-H1_B1_P1_07 | G8: GAGGAGGGCAGCAAACGGAACGATAGGGCAAAGGTTTCTGCAGCG | H8: B-H1_B1_P2_07 | I8: CCTGCGAGAGGCGCACCTGGATATATAGAAGAGTCTTCCTTTACG | J8: B1_P1 (B-H1)_7; B-H17_HCR_P1B1 | K8: B1_P2 (B-H1)_7; B-H17_HCR_P1B2 | L8: CGATAGGGCAAAGGTTTCTGCAGCG | M8: CCTGCGAGAGGCGCACCTGGATATA | N8: =LEN(L8) -> 25 | O8: =LEN(M8) -> 25 | P8: =IF(N8=0,"",(N8-LEN(SUBSTITUTE(SUBSTITUTE(L8,"G",""),"C","")))/N8) -> 0.56 | Q8: =IF(O8=0,"",(O8-LEN(SUBSTITUTE(SUBSTITUTE(M8,"G",""),"C","")))/O8) -> 0.6 | S8: No template | U8: genome position | V8: Jeriel_HCRoligosequences › B-H1 | X8: Both halves | Y8: P2 named as B-H17_HCR_P1B2
A9: JL-001-08 | B9: JL-001 | C9: B-H1 | D9: B1 | E9: 8 | F9: B-H1_B1_P1_08 | G9: GAGGAGGGCAGCAAACGGAAGTGAGCTGACGGCCCCGGGAGGCCG | H9: B-H1_B1_P2_08 | I9: GAGAGCTGGAGCCCCCAGAGAGCCGTAGAAGAGTCTTCCTTTACG | J9: B1_P1 (B-H1)_8; B-H18_HCR_P1B1 | K9: B1_P2 (B-H1)_8; B-H18_HCR_P1B2 | L9: GTGAGCTGACGGCCCCGGGAGGCCG | M9: GAGAGCTGGAGCCCCCAGAGAGCCG | N9: =LEN(L9) -> 25 | O9: =LEN(M9) -> 25 | P9: =IF(N9=0,"",(N9-LEN(SUBSTITUTE(SUBSTITUTE(L9,"G",""),"C","")))/N9) -> 0.8 | Q9: =IF(O9=0,"",(O9-LEN(SUBSTITUTE(SUBSTITUTE(M9,"G",""),"C","")))/O9) -> 0.72 | S9: No template | U9: genome position | V9: Jeriel_HCRoligosequences › B-H1 | X9: Both halves | Y9: P2 named as B-H18_HCR_P1B2
A10: JL-002-01 | B10: JL-002 | C10: bowel | D10: B1 | E10: 1 | F10: bowel_B1_P1_01 | G10: GAGGAGGGCAGCAAACGGAAGCACCGAGGAATGCACCAGGTGGAC | H10: bowel_B1_P2_01 | I10: TTGGCAGCAGTTGGCGAAGGACCCGTAGAAGAGTCTTCCTTTACG | J10: B1_P1 (bowel)_1 | K10: B1_P2 (bowel)_1 | L10: GCACCGAGGAATGCACCAGGTGGAC | M10: TTGGCAGCAGTTGGCGAAGGACCCG | N10: =LEN(L10) -> 25 | O10: =LEN(M10) -> 25 | P10: =IF(N10=0,"",(N10-LEN(SUBSTITUTE(SUBSTITUTE(L10,"G",""),"C","")))/N10) -> 0.64 | Q10: =IF(O10=0,"",(O10-LEN(SUBSTITUTE(SUBSTITUTE(M10,"G",""),"C","")))/O10) -> 0.64 | S10: No template | U10: genome position | V10: Jeriel_HCRoligosequences › bowel | X10: Both halves
A11: JL-002-02 | B11: JL-002 | C11: bowel | D11: B1 | E11: 2 | F11: bowel_B1_P1_02 | G11: GAGGAGGGCAGCAAACGGAAAGCCCCGGGAGGAAATAGCCCAGCA | H11: bowel_B1_P2_02 | I11: TAGATGTGGATGCATTTGATGAGGATAGAAGAGTCTTCCTTTACG | J11: B1_P1 (bowel)_2 | K11: B1_P2 (bowel)_2 | L11: AGCCCCGGGAGGAAATAGCCCAGCA | M11: TAGATGTGGATGCATTTGATGAGGA | N11: =LEN(L11) -> 25 | O11: =LEN(M11) -> 25 | P11: =IF(N11=0,"",(N11-LEN(SUBSTITUTE(SUBSTITUTE(L11,"G",""),"C","")))/N11) -> 0.64 | Q11: =IF(O11=0,"",(O11-LEN(SUBSTITUTE(SUBSTITUTE(M11,"G",""),"C","")))/O11) -> 0.4 | S11: No template | U11: genome position | V11: Jeriel_HCRoligosequences › bowel | X11: Both halves
A12: JL-002-03 | B12: JL-002 | C12: bowel | D12: B1 | E12: 3 | F12: bowel_B1_P1_03 | G12: GAGGAGGGCAGCAAACGGAATAGGCCTCGACGCTCTGCCTGGGGC | H12: bowel_B1_P2_03 | I12: TGCAAAATTTACAGATGAACTGTTTTAGAAGAGTCTTCCTTTACG | J12: B1_P1 (bowel)_3 | K12: B1_P2 (bowel)_3 | L12: TAGGCCTCGACGCTCTGCCTGGGGC | M12: TGCAAAATTTACAGATGAACTGTTT | N12: =LEN(L12) -> 25 | O12: =LEN(M12) -> 25 | P12: =IF(N12=0,"",(N12-LEN(SUBSTITUTE(SUBSTITUTE(L12,"G",""),"C","")))/N12) -> 0.72 | Q12: =IF(O12=0,"",(O12-LEN(SUBSTITUTE(SUBSTITUTE(M12,"G",""),"C","")))/O12) -> 0.28 | S12: No template | U12: genome position | V12: Jeriel_HCRoligosequences › bowel | X12: Both halves
A13: JL-002-04 | B13: JL-002 | C13: bowel | D13: B1 | E13: 4 | F13: bowel_B1_P1_04 | G13: GAGGAGGGCAGCAAACGGAACTTTCGTGGATAAGCAAATTGTAGG | H13: bowel_B1_P2_04 | I13: GAATAGGGACGCTCGTCGGTGTGTGTAGAAGAGTCTTCCTTTACG | J13: B1_P1 (bowel)_4 | K13: B1_P2 (bowel)_4 | L13: CTTTCGTGGATAAGCAAATTGTAGG | M13: GAATAGGGACGCTCGTCGGTGTGTG | N13: =LEN(L13) -> 25 | O13: =LEN(M13) -> 25 | P13: =IF(N13=0,"",(N13-LEN(SUBSTITUTE(SUBSTITUTE(L13,"G",""),"C","")))/N13) -> 0.4 | Q13: =IF(O13=0,"",(O13-LEN(SUBSTITUTE(SUBSTITUTE(M13,"G",""),"C","")))/O13) -> 0.6 | S13: No template | U13: genome position | V13: Jeriel_HCRoligosequences › bowel | X13: Both halves
A14: JL-002-05 | B14: JL-002 | C14: bowel | D14: B1 | E14: 5 | F14: bowel_B1_P1_05 | G14: GAGGAGGGCAGCAAACGGAATAAGTGATCCTGTCTTCTGAATGCC | H14: bowel_B1_P2_05 | I14: TTTTGAATGTATGTACCTATGATCTTAGAAGAGTCTTCCTTTACG | J14: B1_P1 (bowel)_5 | K14: B1_P2 (bowel)_5 | L14: TAAGTGATCCTGTCTTCTGAATGCC | M14: TTTTGAATGTATGTACCTATGATCT | N14: =LEN(L14) -> 25 | O14: =LEN(M14) -> 25 | P14: =IF(N14=0,"",(N14-LEN(SUBSTITUTE(SUBSTITUTE(L14,"G",""),"C","")))/N14) -> 0.44 | Q14: =IF(O14=0,"",(O14-LEN(SUBSTITUTE(SUBSTITUTE(M14,"G",""),"C","")))/O14) -> 0.28 | S14: No template | U14: genome position | V14: Jeriel_HCRoligosequences › bowel | X14: Both halves
A15: JL-002-06 | B15: JL-002 | C15: bowel | D15: B1 | E15: 6 | F15: bowel_B1_P1_06 | G15: GAGGAGGGCAGCAAACGGAAGGCAGAATCCTTTTCCACATTCTGT | H15: bowel_B1_P2_06 | I15: TCTTGTGGACAGCTAAAGTCCGCGATAGAAGAGTCTTCCTTTACG | J15: B1_P1 (bowel)_6 | K15: B1_P2 (bowel)_6 | L15: GGCAGAATCCTTTTCCACATTCTGT | M15: TCTTGTGGACAGCTAAAGTCCGCGA | N15: =LEN(L15) -> 25 | O15: =LEN(M15) -> 25 | P15: =IF(N15=0,"",(N15-LEN(SUBSTITUTE(SUBSTITUTE(L15,"G",""),"C","")))/N15) -> 0.44 | Q15: =IF(O15=0,"",(O15-LEN(SUBSTITUTE(SUBSTITUTE(M15,"G",""),"C","")))/O15) -> 0.52 | S15: No template | U15: genome position | V15: Jeriel_HCRoligosequences › bowel | X15: Both halves
A16: JL-002-07 | B16: JL-002 | C16: bowel | D16: B1 | E16: 7 | F16: bowel_B1_P1_07 | G16: GAGGAGGGCAGCAAACGGAACTGCAGACAGGACACTTGTGGGGAG | H16: bowel_B1_P2_07 | I16: AGATTCGAGCGCTGGTTGAAACTACTAGAAGAGTCTTCCTTTACG | J16: B1_P1 (bowel)_7 | K16: B1_P2 (bowel)_7 | L16: CTGCAGACAGGACACTTGTGGGGAG | M16: AGATTCGAGCGCTGGTTGAAACTAC | N16: =LEN(L16) -> 25 | O16: =LEN(M16) -> 25 | P16: =IF(N16=0,"",(N16-LEN(SUBSTITUTE(SUBSTITUTE(L16,"G",""),"C","")))/N16) -> 0.6 | Q16: =IF(O16=0,"",(O16-LEN(SUBSTITUTE(SUBSTITUTE(M16,"G",""),"C","")))/O16) -> 0.48 | S16: No template | U16: genome position | V16: Jeriel_HCRoligosequences › bowel | X16: Both halves
A17: JL-002-08 | B17: JL-002 | C17: bowel | D17: B1 | E17: 8 | F17: bowel_B1_P1_08 | G17: GAGGAGGGCAGCAAACGGAATTCATAAGGTTTGTGGTCAGTATGG | H17: bowel_B1_P2_08 | I17: TCTGAATACTTTTCCACATGAATTATAGAAGAGTCTTCCTTTACG | J17: B1_P1 (bowel)_8 | K17: B1_P2 (bowel)_8 | L17: TTCATAAGGTTTGTGGTCAGTATGG | M17: TCTGAATACTTTTCCACATGAATTA | N17: =LEN(L17) -> 25 | O17: =LEN(M17) -> 25 | P17: =IF(N17=0,"",(N17-LEN(SUBSTITUTE(SUBSTITUTE(L17,"G",""),"C","")))/N17) -> 0.4 | Q17: =IF(O17=0,"",(O17-LEN(SUBSTITUTE(SUBSTITUTE(M17,"G",""),"C","")))/O17) -> 0.28 | S17: No template | U17: genome position | V17: Jeriel_HCRoligosequences › bowel | X17: Both halves
A18: JL-002-09 | B18: JL-002 | C18: bowel | D18: B1 | E18: 9 | F18: bowel_B1_P1_09 | G18: GAGGAGGGCAGCAAACGGAACTACAGCATGTGTTAAAGCATGCCT | H18: bowel_B1_P2_09 | I18: CCAATACGTCACCTGCTGGAACGTCTAGAAGAGTCTTCCTTTACG | J18: B1_P1 (bowel)_9 | K18: B1_P2 (bowel)_9 | L18: CTACAGCATGTGTTAAAGCATGCCT | M18: CCAATACGTCACCTGCTGGAACGTC | N18: =LEN(L18) -> 25 | O18: =LEN(M18) -> 25 | P18: =IF(N18=0,"",(N18-LEN(SUBSTITUTE(SUBSTITUTE(L18,"G",""),"C","")))/N18) -> 0.44 | Q18: =IF(O18=0,"",(O18-LEN(SUBSTITUTE(SUBSTITUTE(M18,"G",""),"C","")))/O18) -> 0.56 | S18: No template | U18: genome position | V18: Jeriel_HCRoligosequences › bowel | X18: Both halves
A19: JL-002-10 | B19: JL-002 | C19: bowel | D19: B1 | E19: 10 | F19: bowel_B1_P1_10 | G19: GAGGAGGGCAGCAAACGGAATCATTAGGTGAACCAGGTCTACCAA | H19: bowel_B1_P2_10 | I19: TCAGGGTCATCGTCATCGAAACCGGTAGAAGAGTCTTCCTTTACG | J19: B1_P1 (bowel)_10 | K19: B1_P2 (bowel)_10 | L19: TCATTAGGTGAACCAGGTCTACCAA | M19: TCAGGGTCATCGTCATCGAAACCGG | N19: =LEN(L19) -> 25 | O19: =LEN(M19) -> 25 | P19: =IF(N19=0,"",(N19-LEN(SUBSTITUTE(SUBSTITUTE(L19,"G",""),"C","")))/N19) -> 0.44 | Q19: =IF(O19=0,"",(O19-LEN(SUBSTITUTE(SUBSTITUTE(M19,"G",""),"C","")))/O19) -> 0.56 | S19: No template | U19: genome position | V19: Jeriel_HCRoligosequences › bowel | X19: Both halves
A20: JL-003-01 | B20: JL-003 | C20: btlfgfr | D20: B1 | E20: 1 | F20: btlfgfr_B1_P1_01 | G20: GAGGAGGGCAGCAAACGGAATTCGTTAGTTCGTCGATTGCCATAG | H20: btlfgfr_B1_P2_01 | I20: TTGCAGGTATAGTTTCCGTTATCGGTAGAAGAGTCTTCCTTTACG | J20: B1_P1 (btl)_1 | K20: B1_P2 (btl)_1 | L20: TTCGTTAGTTCGTCGATTGCCATAG | M20: TTGCAGGTATAGTTTCCGTTATCGG | N20: =LEN(L20) -> 25 | O20: =LEN(M20) -> 25 | P20: =IF(N20=0,"",(N20-LEN(SUBSTITUTE(SUBSTITUTE(L20,"G",""),"C","")))/N20) -> 0.44 | Q20: =IF(O20=0,"",(O20-LEN(SUBSTITUTE(SUBSTITUTE(M20,"G",""),"C","")))/O20) -> 0.44 | S20: No template | U20: genome position | V20: Jeriel_HCRoligosequences › btlfgfr | X20: Both halves
A21: JL-003-02 | B21: JL-003 | C21: btlfgfr | D21: B1 | E21: 2 | F21: btlfgfr_B1_P1_02 | G21: GAGGAGGGCAGCAAACGGAATAGTGTGTAAGTATGTTCAACACAT | H21: btlfgfr_B1_P2_02 | I21: CTTAGATGGATAGCGTTCTTGTATATAGAAGAGTCTTCCTTTACG | J21: B1_P1 (btl)_2 | K21: B1_P2 (btl)_2 | L21: TAGTGTGTAAGTATGTTCAACACAT | M21: CTTAGATGGATAGCGTTCTTGTATA | N21: =LEN(L21) -> 25 | O21: =LEN(M21) -> 25 | P21: =IF(N21=0,"",(N21-LEN(SUBSTITUTE(SUBSTITUTE(L21,"G",""),"C","")))/N21) -> 0.32 | Q21: =IF(O21=0,"",(O21-LEN(SUBSTITUTE(SUBSTITUTE(M21,"G",""),"C","")))/O21) -> 0.36 | S21: No template | U21: genome position | V21: Jeriel_HCRoligosequences › btlfgfr | X21: Both halves
... A91: JL-010-10 | B91: JL-010 | C91: nubbin | D91: B1 | E91: 10 | F91: nubbin_B1_P1_10 | G91: GAGGAGGGCAGCAAACGGAATGCGCAGGAAGGCCTTCTCCAGCGC | H91: nubbin_B1_P2_10 | I91: CGATCTCCTCACTGGTGGGCTTGGGTAGAAGAGTCTTCCTTTACG | J91: B1_P1 (nubbin-like)_10 | K91: B1_P2 (nubbin-like)_10 | L91: TGCGCAGGAAGGCCTTCTCCAGCGC | M91: CGATCTCCTCACTGGTGGGCTTGGG | N91: =LEN(L91) -> 25 | O91: =LEN(M91) -> 25 | P91: =IF(N91=0,"",(N91-LEN(SUBSTITUTE(SUBSTITUTE(L91,"G",""),"C","")))/N91) -> 0.68 | Q91: =IF(O91=0,"",(O91-LEN(SUBSTITUTE(SUBSTITUTE(M91,"G",""),"C","")))/O91) -> 0.64 | S91: No template | U91: genome position | V91: Jeriel_HCRoligosequences › nubbin | X91: Both halves
A92: JL-011-01 | B92: JL-011 | C92: pannier | D92: B1 | E92: 1 | F92: pannier_B1_P1_01 | G92: GAGGAGGGCAGCAAACGGAAGGGTTCTGATCCGTGGACGGGTACG | H92: pannier_B1_P2_01 | I92: GAACTGTCAACCCCGATGCTGGGGTTAGAAGAGTCTTCCTTTACG | J92: B1_P1 (pnr)_1 | K92: B1_P2 (pnr)_1 | L92: GGGTTCTGATCCGTGGACGGGTACG | M92: GAACTGTCAACCCCGATGCTGGGGT | N92: =LEN(L92) -> 25 | O92: =LEN(M92) -> 25 | P92: =IF(N92=0,"",(N92-LEN(SUBSTITUTE(SUBSTITUTE(L92,"G",""),"C","")))/N92) -> 0.64 | Q92: =IF(O92=0,"",(O92-LEN(SUBSTITUTE(SUBSTITUTE(M92,"G",""),"C","")))/O92) -> 0.6 | S92: No template | U92: genome position | V92: Jeriel_HCRoligosequences › pannier | X92: Both halves | Y92: identical to Dragonaut9000 S004
A93: JL-011-02 | B93: JL-011 | C93: pannier | D93: B1 | E93: 2 | F93: pannier_B1_P1_02 | G93: GAGGAGGGCAGCAAACGGAACTCTTTCAGAGCGTACGGGTTGCTC | H93: pannier_B1_P2_02 | I93: TGTCCAAGCTGACATCTCGCCGTTTTAGAAGAGTCTTCCTTTACG | J93: B1_P1 (pnr)_2 | K93: B1_P2 (pnr)_2 | L93: CTCTTTCAGAGCGTACGGGTTGCTC | M93: TGTCCAAGCTGACATCTCGCCGTTT | N93: =LEN(L93) -> 25 | O93: =LEN(M93) -> 25 | P93: =IF(N93=0,"",(N93-LEN(SUBSTITUTE(SUBSTITUTE(L93,"G",""),"C","")))/N93) -> 0.56 | Q93: =IF(O93=0,"",(O93-LEN(SUBSTITUTE(SUBSTITUTE(M93,"G",""),"C","")))/O93) -> 0.52 | S93: No template | U93: genome position | V93: Jeriel_HCRoligosequences › pannier | X93: Both halves | Y93: identical to Dragonaut9000 S004
A94: JL-011-03 | B94: JL-011 | C94: pannier | D94: B1 | E94: 3 | F94: pannier_B1_P1_03 | G94: GAGGAGGGCAGCAAACGGAAGGTCGTAGGGGTAGTAGCCGCCGGA | H94: pannier_B1_P2_03 | I94: CTCCGTATCCGTAGGCCGCGAGCGTTAGAAGAGTCTTCCTTTACG | J94: B1_P1 (pnr)_3 | K94: B1_P2 (pnr)_3 | L94: GGTCGTAGGGGTAGTAGCCGCCGGA | M94: CTCCGTATCCGTAGGCCGCGAGCGT | N94: =LEN(L94) -> 25 | O94: =LEN(M94) -> 25 | P94: =IF(N94=0,"",(N94-LEN(SUBSTITUTE(SUBSTITUTE(L94,"G",""),"C","")))/N94) -> 0.68 | Q94: =IF(O94=0,"",(O94-LEN(SUBSTITUTE(SUBSTITUTE(M94,"G",""),"C","")))/O94) -> 0.68 | S94: No template | U94: genome position | V94: Jeriel_HCRoligosequences › pannier | X94: Both halves | Y94: identical to Dragonaut9000 S004
A95: JL-011-04 | B95: JL-011 | C95: pannier | D95: B1 | E95: 4 | F95: pannier_B1_P1_04 | G95: GAGGAGGGCAGCAAACGGAATCGCGCGTCGCGTTTTTCCGCCTGG | H95: pannier_B1_P2_04 | I95: AGCCACGCCTTTAGTGTTGCGGTGGTAGAAGAGTCTTCCTTTACG | J95: B1_P1 (pnr)_4 | K95: B1_P2 (pnr)_4 | L95: TCGCGCGTCGCGTTTTTCCGCCTGG | M95: AGCCACGCCTTTAGTGTTGCGGTGG | N95: =LEN(L95) -> 25 | O95: =LEN(M95) -> 25 | P95: =IF(N95=0,"",(N95-LEN(SUBSTITUTE(SUBSTITUTE(L95,"G",""),"C","")))/N95) -> 0.68 | Q95: =IF(O95=0,"",(O95-LEN(SUBSTITUTE(SUBSTITUTE(M95,"G",""),"C","")))/O95) -> 0.6 | S95: No template | U95: genome position | V95: Jeriel_HCRoligosequences › pannier | X95: Both halves
A96: JL-011-05 | B96: JL-011 | C96: pannier | D96: B1 | E96: 5 | F96: pannier_B1_P1_05 | G96: GAGGAGGGCAGCAAACGGAACTTCTCCCCCTTGGTCGGGTACGGG | H96: pannier_B1_P2_05 | I96: CATCTTGGTGATGATGGCCAACATTTAGAAGAGTCTTCCTTTACG | J96: B1_P1 (pnr)_5 | K96: B1_P2 (pnr)_5 | L96: CTTCTCCCCCTTGGTCGGGTACGGG | M96: CATCTTGGTGATGATGGCCAACATT | N96: =LEN(L96) -> 25 | O96: =LEN(M96) -> 25 | P96: =IF(N96=0,"",(N96-LEN(SUBSTITUTE(SUBSTITUTE(L96,"G",""),"C","")))/N96) -> 0.68 | Q96: =IF(O96=0,"",(O96-LEN(SUBSTITUTE(SUBSTITUTE(M96,"G",""),"C","")))/O96) -> 0.44 | S96: No template | U96: genome position | V96: Jeriel_HCRoligosequences › pannier | X96: Both halves
A97: JL-011-06 | B97: JL-011 | C97: pannier | D97: B1 | E97: 6 | F97: pannier_B1_P1_06 | G97: GAGGAGGGCAGCAAACGGAAGCCGGCGCGCGTTCGCGAACCACGT | H97: pannier_B1_P2_06 | I97: AGGTCATCTTGTTCTCCTTCTTGAGTAGAAGAGTCTTCCTTTACG | J97: B1_P1 (pnr)_6 | K97: B1_P2 (pnr)_6 | L97: GCCGGCGCGCGTTCGCGAACCACGT | M97: AGGTCATCTTGTTCTCCTTCTTGAG | N97: =LEN(L97) -> 25 | O97: =LEN(M97) -> 25 | P97: =IF(N97=0,"",(N97-LEN(SUBSTITUTE(SUBSTITUTE(L97,"G",""),"C","")))/N97) -> 0.76 | Q97: =IF(O97=0,"",(O97-LEN(SUBSTITUTE(SUBSTITUTE(M97,"G",""),"C","")))/O97) -> 0.44 | S97: No template | U97: genome position | V97: Jeriel_HCRoligosequences › pannier | X97: Both halves
A98: JL-011-07 | B98: JL-011 | C98: pannier | D98: B1 | E98: 7 | F98: pannier_B1_P1_07 | G98: GAGGAGGGCAGCAAACGGAAAGCATGGTGTCGTCGTCGTCGTCTG | H98: pannier_B1_P2_07 | I98: TTGTCGTCGTCTTTCTCCTCGTCGGTAGAAGAGTCTTCCTTTACG | J98: B1_P1 (pnr)_7 | K98: B1_P2 (pnr)_7 | L98: AGCATGGTGTCGTCGTCGTCGTCTG | M98: TTGTCGTCGTCTTTCTCCTCGTCGG | N98: =LEN(L98) -> 25 | O98: =LEN(M98) -> 25 | P98: =IF(N98=0,"",(N98-LEN(SUBSTITUTE(SUBSTITUTE(L98,"G",""),"C","")))/N98) -> 0.6 | Q98: =IF(O98=0,"",(O98-LEN(SUBSTITUTE(SUBSTITUTE(M98,"G",""),"C","")))/O98) -> 0.56 | S98: No template | U98: genome position | V98: Jeriel_HCRoligosequences › pannier | X98: Both halves
A99: JL-011-08 | B99: JL-011 | C99: pannier | D99: B1 | E99: 8 | F99: pannier_B1_P1_08 | G99: GAGGAGGGCAGCAAACGGAAAAGCTCGTCCCCCTTCCTTTCCTCA | H99: pannier_B1_P2_08 | I99: GAGTAGTTGACTGTGCATGCCCTGGTAGAAGAGTCTTCCTTTACG | J99: B1_P1 (pnr)_8 | K99: B1_P2 (pnr)_8 | L99: AAGCTCGTCCCCCTTCCTTTCCTCA | M99: GAGTAGTTGACTGTGCATGCCCTGG | N99: =LEN(L99) -> 25 | O99: =LEN(M99) -> 25 | P99: =IF(N99=0,"",(N99-LEN(SUBSTITUTE(SUBSTITUTE(L99,"G",""),"C","")))/N99) -> 0.56 | Q99: =IF(O99=0,"",(O99-LEN(SUBSTITUTE(SUBSTITUTE(M99,"G",""),"C","")))/O99) -> 0.56 | S99: No template | U99: genome position | V99: Jeriel_HCRoligosequences › pannier | X99: Both halves
A100: JL-011-09 | B100: JL-011 | C100: pannier | D100: B1 | E100: 9 | F100: pannier_B1_P1_09 | G100: GAGGAGGGCAGCAAACGGAAAGTCTGAAGTCCCTCGCTTGGACTC | H100: pannier_B1_P2_09 | I100: GCTTCGACGCTGGTATCGGCACGCCTAGAAGAGTCTTCCTTTACG | J100: B1_P1 (pnr)_9 | K100: B1_P2 (pnr)_9 | L100: AGTCTGAAGTCCCTCGCTTGGACTC | M100: GCTTCGACGCTGGTATCGGCACGCC | N100: =LEN(L100) -> 25 | O100: =LEN(M100) -> 25 | P100: =IF(N100=0,"",(N100-LEN(SUBSTITUTE(SUBSTITUTE(L100,"G",""),"C","")))/N100) -> 0.56 | Q100: =IF(O100=0,"",(O100-LEN(SUBSTITUTE(SUBSTITUTE(M100,"G",""),"C","")))/O100) -> 0.68 | S100: No template | U100: genome position | V100: Jeriel_HCRoligosequences › pannier | X100: Both halves
A101: JL-012-01 | B101: JL-012 | C101: rotund | D101: B1 | E101: 1 | F101: rotund_B1_P1_01 | G101: GAGGAGGGCAGCAAACGGAATAAGTACGGACGGCTTTATCTCAGG | H101: rotund_B1_P2_01 | I101: GTAGACCACTTTTGAATTCGGATAATAGAAGAGTCTTCCTTTACG | J101: B1_P1 (rotund)_1 | K101: B1_P2 (rotund)_1 | L101: TAAGTACGGACGGCTTTATCTCAGG | M101: GTAGACCACTTTTGAATTCGGATAA | N101: =LEN(L101) -> 25 | O101: =LEN(M101) -> 25 | P101: =IF(N101=0,"",(N101-LEN(SUBSTITUTE(SUBSTITUTE(L101,"G",""),"C","")))/N101) -> 0.48 | Q101: =IF(O101=0,"",(O101-LEN(SUBSTITUTE(SUBSTITUTE(M101,"G",""),"C","")))/O101) -> 0.36 | S101: No template | U101: genome position | V101: Jeriel_HCRoligosequences › rotund | X101: Both halves
A102: JL-012-02 | B102: JL-012 | C102: rotund | D102: B1 | E102: 2 | F102: rotund_B1_P1_02 | G102: GAGGAGGGCAGCAAACGGAACGCTGAATGTCATTCTCTTGGTCAT | H102: rotund_B1_P2_02 | I102: TTTCCATCGTCGTGCGGTGTCATTTTAGAAGAGTCTTCCTTTACG | J102: B1_P1 (rotund)_2 | K102: B1_P2 (rotund)_2 | L102: CGCTGAATGTCATTCTCTTGGTCAT | M102: TTTCCATCGTCGTGCGGTGTCATTT | N102: =LEN(L102) -> 25 | O102: =LEN(M102) -> 25 | P102: =IF(N102=0,"",(N102-LEN(SUBSTITUTE(SUBSTITUTE(L102,"G",""),"C","")))/N102) -> 0.44 | Q102: =IF(O102=0,"",(O102-LEN(SUBSTITUTE(SUBSTITUTE(M102,"G",""),"C","")))/O102) -> 0.48 | S102: No template | U102: genome position | V102: Jeriel_HCRoligosequences › rotund | X102: Both halves
A103: JL-012-03 | B103: JL-012 | C103: rotund | D103: B1 | E103: 3 | F103: rotund_B1_P1_03 | G103: GAGGAGGGCAGCAAACGGAATCCGCCGTTTTCTGATAAAGGCGTT | H103: rotund_B1_P2_03 | I103: GAACACCTTTTCCTCTTGAATGCTTTAGAAGAGTCTTCCTTTACG | J103: B1_P1 (rotund)_3 | K103: B1_P2 (rotund)_3 | L103: TCCGCCGTTTTCTGATAAAGGCGTT | M103: GAACACCTTTTCCTCTTGAATGCTT | N103: =LEN(L103) -> 25 | O103: =LEN(M103) -> 25 | P103: =IF(N103=0,"",(N103-LEN(SUBSTITUTE(SUBSTITUTE(L103,"G",""),"C","")))/N103) -> 0.48 | Q103: =IF(O103=0,"",(O103-LEN(SUBSTITUTE(SUBSTITUTE(M103,"G",""),"C","")))/O103) -> 0.4 | S103: No template | U103: genome position | V103: Jeriel_HCRoligosequences › rotund | X103: Both halves
A104: JL-013-01 | B104: JL-013 | C104: scr | D104: B1 | E104: 1 | F104: scr_B1_P1_01 | G104: GAGGAGGGCAGCAAACGGAAGCTGTAGCATTTGGATTATAATAGT | H104: scr_B1_P2_01 | I104: GGTGAATAACATGTATTTGGATACGTAGAAGAGTCTTCCTTTACG | J104: B1_P1 (scr)_1 | K104: B1_P2 (scr)_1 | L104: GCTGTAGCATTTGGATTATAATAGT | M104: GGTGAATAACATGTATTTGGATACG | N104: =LEN(L104) -> 25 | O104: =LEN(M104) -> 25 | P104: =IF(N104=0,"",(N104-LEN(SUBSTITUTE(SUBSTITUTE(L104,"G",""),"C","")))/N104) -> 0.32 | Q104: =IF(O104=0,"",(O104-LEN(SUBSTITUTE(SUBSTITUTE(M104,"G",""),"C","")))/O104) -> 0.36 | S104: No template | U104: genome position | V104: Jeriel_HCRoligosequences › scr | X104: Both halves
A105: JL-013-02 | B105: JL-013 | C105: scr | D105: B1 | E105: 2 | F105: scr_B1_P1_02 | G105: GAGGAGGGCAGCAAACGGAACGTCGCATACGGATGTTGCGGGTAA | H105: scr_B1_P2_02 | I105: TGGTTGCATGTGAGCACCGGCTGCCTAGAAGAGTCTTCCTTTACG | J105: B1_P1 (scr)_2 | K105: B1_P2 (scr)_2 | L105: CGTCGCATACGGATGTTGCGGGTAA | M105: TGGTTGCATGTGAGCACCGGCTGCC | N105: =LEN(L105) -> 25 | O105: =LEN(M105) -> 25 | P105: =IF(N105=0,"",(N105-LEN(SUBSTITUTE(SUBSTITUTE(L105,"G",""),"C","")))/N105) -> 0.56 | Q105: =IF(O105=0,"",(O105-LEN(SUBSTITUTE(SUBSTITUTE(M105,"G",""),"C","")))/O105) -> 0.64 | S105: No template | U105: genome position | V105: Jeriel_HCRoligosequences › scr | X105: Both halves
A106: JL-013-03 | B106: JL-013 | C106: scr | D106: B1 | E106: 3 | F106: scr_B1_P1_03 | G106: GAGGAGGGCAGCAAACGGAACAAGTCTTTGTGGATGCAGTTGTGT | H106: scr_B1_P2_03 | I106: GTTGGTGCACATGGCTCGCCGTGCCTAGAAGAGTCTTCCTTTACG | J106: B1_P1 (scr)_3 | K106: B1_P2 (scr)_3 | L106: CAAGTCTTTGTGGATGCAGTTGTGT | M106: GTTGGTGCACATGGCTCGCCGTGCC | N106: =LEN(L106) -> 25 | O106: =LEN(M106) -> 25 | P106: =IF(N106=0,"",(N106-LEN(SUBSTITUTE(SUBSTITUTE(L106,"G",""),"C","")))/N106) -> 0.44 | Q106: =IF(O106=0,"",(O106-LEN(SUBSTITUTE(SUBSTITUTE(M106,"G",""),"C","")))/O106) -> 0.68 | S106: No template | U106: genome position | V106: Jeriel_HCRoligosequences › scr | X106: Both halves
... A402: JL-047-06 | B402: JL-047 | C402: fringe | D402: B3 | E402: 6 | F402: fringe_B3_P1_06 | G402: GTCCCTGCCTCTATATCTTTGTTGGTAGGCTTCTTGAACATATCT | H402: fringe_B3_P2_06 | I402: TGCGAACCAAAAAGTGTATAATAACTTCCACTCAACTTTAACCCG | J402: B3_P1(fringe)_6 | K402: B3_P2(fringe)_6 | L402: GTTGGTAGGCTTCTTGAACATATCT | M402: TGCGAACCAAAAAGTGTATAATAAC | N402: =LEN(L402) -> 25 | O402: =LEN(M402) -> 25 | P402: =IF(N402=0,"",(N402-LEN(SUBSTITUTE(SUBSTITUTE(L402,"G",""),"C","")))/N402) -> 0.4 | Q402: =IF(O402=0,"",(O402-LEN(SUBSTITUTE(SUBSTITUTE(M402,"G",""),"C","")))/O402) -> 0.32 | S402: No template | U402: genome position | V402: Jeriel_HCRoligosequences › fringe | X402: Both halves
A403: JL-048-01 | B403: JL-048 | C403: hh | D403: B3 | E403: 1 | F403: hh_B3_P1_01 | G403: GTCCCTGCCTCTATATCTTTATCCTTAAACTCTATGTCCGGGTTA | H403: hh_B3_P2_01 | I403: GAGGCGGTCGGCTCCGGTGCCCTCGTTCCACTCAACTTTAACCCG | J403: B3_P1(hh1.1)_1 | K403: B3_P2(hh1.1)_1 | L403: ATCCTTAAACTCTATGTCCGGGTTA | M403: GAGGCGGTCGGCTCCGGTGCCCTCG | N403: =LEN(L403) -> 25 | O403: =LEN(M403) -> 25 | P403: =IF(N403=0,"",(N403-LEN(SUBSTITUTE(SUBSTITUTE(L403,"G",""),"C","")))/N403) -> 0.4 | Q403: =IF(O403=0,"",(O403-LEN(SUBSTITUTE(SUBSTITUTE(M403,"G",""),"C","")))/O403) -> 0.8 | S403: No template | U403: genome position | V403: Jeriel_HCRoligosequences › hh | X403: Both halves | Y403: identical to Dragonaut9000 S143
A404: JL-048-02 | B404: JL-048 | C404: hh | D404: B3 | E404: 2 | F404: hh_B3_P1_02 | G404: GTCCCTGCCTCTATATCTTTTGATGGCGAGCGTGTTCAACTTCTC | H404: hh_B3_P2_02 | I404: GAACCCCCGGCCACTGGTTCATCACTTCCACTCAACTTTAACCCG | J404: B3_P1(hh1.1)_2 | K404: B3_P2(hh1.1)_2 | L404: TGATGGCGAGCGTGTTCAACTTCTC | M404: GAACCCCCGGCCACTGGTTCATCAC | N404: =LEN(L404) -> 25 | O404: =LEN(M404) -> 25 | P404: =IF(N404=0,"",(N404-LEN(SUBSTITUTE(SUBSTITUTE(L404,"G",""),"C","")))/N404) -> 0.52 | Q404: =IF(O404=0,"",(O404-LEN(SUBSTITUTE(SUBSTITUTE(M404,"G",""),"C","")))/O404) -> 0.64 | S404: No template | U404: genome position | V404: Jeriel_HCRoligosequences › hh | X404: Both halves | Y404: identical to Dragonaut9000 S143
...

Sheet Templates
A1: Template_ID | B1: Gene (short) | C1: Organism | D1: Header as written in source | E1: Source file | F1: Length (nt) | G1: # pairs assigned here | H1: Sequence (sense, 5′→3′)

Sheet Amplifiers
A1: Amplifier | B1: Fluorophore (lab default) | C1: P1 5′ initiator half | D1: P1 spacer | E1: P2 spacer | F1: P2 3′ initiator half | G1: # sets in this file | H1: # pairs in this file
A2: B1 | B2: AF546 | C2: GAGGAGGGCAGCAAACGG | D2: AA | E2: TA | F2: GAAGAGTCTTCCTTTACG | G2: =COUNTIF(Probe_Sets!$I:$I,A2) -> 17 | H2: =SUMIF(Probe_Sets!$I:$I,A2,Probe_Sets!$K:$K) -> 158
A3: B2 | B3: AF647 | C3: CCTCGTAAATCCTCATCA | D3: AA | E3: AA | F3: ATCATCCAGTAAACCGCC | G3: =COUNTIF(Probe_Sets!$I:$I,A3) -> 20 | H3: =SUMIF(Probe_Sets!$I:$I,A3,Probe_Sets!$K:$K) -> 163
A4: B3 | B4: AF488 | C4: GTCCCTGCCTCTATATCT | D4: TT | E4: TT | F4: CCACTCAACTTTAACCCG | G4: =COUNTIF(Probe_Sets!$I:$I,A4) -> 19 | H4: =SUMIF(Probe_Sets!$I:$I,A4,Probe_Sets!$K:$K) -> 152
A5: B4 | B5: AF514 | C5: CCTCAACCTACCTCCAAC | D5: AA | E5: AT | F5: TCTCACCATATTCGCTTC | G5: =COUNTIF(Probe_Sets!$I:$I,A5) -> 0 | H5: =SUMIF(Probe_Sets!$I:$I,A5,Probe_Sets!$K:$K) -> 0
A6: B5 | B6: AF594 | C6: CTCACTCCCAATCTCTAT | D6: AA | E6: AA | F6: CTACCCTACAAATCCAAT | G6: =COUNTIF(Probe_Sets!$I:$I,A6) -> 0 | H6: =SUMIF(Probe_Sets!$I:$I,A6,Probe_Sets!$K:$K) -> 0
